# Goxel 0.15.1
# One line per voxel
# X Y Z RRGGBB
-7 70 98 ffcc66
-6 70 98 ffcc66
-5 70 98 ffcc66
-4 70 98 ffcc66
-3 70 98 ffcc66
-8 71 98 ffcc66
-7 71 98 ffcc66
-6 71 98 ffcc66
-5 71 98 ffcc66
-4 71 98 ffcc66
-3 71 98 ffcc66
-2 71 98 ffcc66
-9 72 98 ffcc66
-8 72 98 ffcc66
-7 72 98 ffcc66
-6 72 98 ffcc66
-5 72 98 ffcc66
-4 72 98 ffcc66
-3 72 98 ffcc66
-2 72 98 ffcc66
-1 72 98 ffcc66
-10 73 98 ffcc66
-9 73 98 ffcc66
-8 73 98 ffcc66
-7 73 98 ffcc66
-6 73 98 ffcc66
-5 73 98 ffcc66
-4 73 98 ffcc66
-3 73 98 ffcc66
-2 73 98 ffcc66
-1 73 98 ffcc66
-10 74 98 ffcc66
-9 74 98 ffcc66
-8 74 98 ffcc66
-7 74 98 ffcc66
-6 74 98 ffcc66
-5 74 98 ffcc66
-4 74 98 ffcc66
-3 74 98 ffcc66
-2 74 98 ffcc66
-1 74 98 ffcc66
-11 75 98 ffcc66
-10 75 98 ffcc66
-9 75 98 ffcc66
-8 75 98 ffcc66
-7 75 98 ffcc66
-6 75 98 ffcc66
-5 75 98 ffcc66
-4 75 98 ffcc66
-3 75 98 ffcc66
-2 75 98 ffcc66
-1 75 98 ffcc66
-12 76 98 ffcc66
-11 76 98 ffcc66
-10 76 98 ffcc66
-9 76 98 ffcc66
-8 76 98 ffcc66
-7 76 98 ffcc66
-6 76 98 ffcc66
-5 76 98 ffcc66
-4 76 98 ffcc66
-3 76 98 ffcc66
-2 76 98 ffcc66
-1 76 98 ffcc66
-13 77 98 ffcc66
-12 77 98 ffcc66
-11 77 98 ffcc66
-10 77 98 ffcc66
-9 77 98 ffcc66
-8 77 98 ffcc66
-7 77 98 ffcc66
-6 77 98 ffcc66
-5 77 98 ffcc66
-4 77 98 ffcc66
-3 77 98 ffcc66
-2 77 98 ffcc66
-1 77 98 ffcc66
-14 78 98 ffcc66
-13 78 98 ffcc66
-12 78 98 ffcc66
-11 78 98 ffcc66
-10 78 98 ffcc66
-9 78 98 ffcc66
-8 78 98 ffcc66
-7 78 98 ffcc66
-6 78 98 ffcc66
-5 78 98 ffcc66
-4 78 98 ffcc66
-3 78 98 ffcc66
-2 78 98 ffcc66
-1 78 98 ffcc66
-14 79 98 ffcc66
-13 79 98 ffcc66
-12 79 98 ffcc66
-11 79 98 ffcc66
-10 79 98 ffcc66
-9 79 98 ffcc66
-8 79 98 ffcc66
-7 79 98 ffcc66
-6 79 98 ffcc66
-5 79 98 ffcc66
-4 79 98 ffcc66
-3 79 98 ffcc66
-2 79 98 ffcc66
-1 79 98 ffcc66
-9 70 99 ffcc66
-8 70 99 ffcc66
-7 70 99 ffcc66
-6 70 99 ffcc66
-5 70 99 ffcc66
-4 70 99 ffcc66
-3 70 99 ffcc66
-11 71 99 ffcc66
-10 71 99 ffcc66
-9 71 99 ffcc66
-8 71 99 ffcc66
-7 71 99 ffcc66
-6 71 99 ee0000
-5 71 99 ee0000
-4 71 99 ee0000
-3 71 99 ffcc66
-2 71 99 ffcc66
-12 72 99 ffcc66
-11 72 99 ffcc66
-10 72 99 ffcc66
-9 72 99 ffcc66
-8 72 99 ffcc66
-7 72 99 ee0000
-6 72 99 ee0000
-5 72 99 ee0000
-4 72 99 ee0000
-3 72 99 ee0000
-2 72 99 ffcc66
-1 72 99 ffcc66
-12 73 99 ffcc66
-11 73 99 ffcc66
-10 73 99 ffcc66
-9 73 99 ffcc66
-8 73 99 ee0000
-7 73 99 ee0000
-6 73 99 ee0000
-5 73 99 ee0000
-4 73 99 ee0000
-3 73 99 ee0000
-2 73 99 ee0000
-1 73 99 ffcc66
-13 74 99 ffcc66
-12 74 99 ffcc66
-11 74 99 ffcc66
-10 74 99 ffcc66
-9 74 99 ee0000
-8 74 99 ee0000
-7 74 99 ee0000
-6 74 99 ee0000
-5 74 99 ee0000
-4 74 99 ee0000
-3 74 99 ee0000
-2 74 99 ee0000
-1 74 99 ee0000
-13 75 99 ffcc66
-12 75 99 ffcc66
-11 75 99 ffcc66
-10 75 99 ffcc66
-9 75 99 ee0000
-8 75 99 ee0000
-7 75 99 ee0000
-6 75 99 ee0000
-5 75 99 ee0000
-4 75 99 ee0000
-3 75 99 ee0000
-2 75 99 ee0000
-1 75 99 ee0000
-14 76 99 ffcc66
-13 76 99 ffcc66
-12 76 99 ffcc66
-11 76 99 ffcc66
-10 76 99 ee0000
-9 76 99 ee0000
-8 76 99 ee0000
-7 76 99 bbbbbb
-6 76 99 bbbbbb
-5 76 99 bbbbbb
-4 76 99 ee0000
-3 76 99 ee0000
-2 76 99 ee0000
-1 76 99 ee0000
-14 77 99 ffcc66
-13 77 99 ffcc66
-12 77 99 ffcc66
-11 77 99 ee0000
-10 77 99 ee0000
-9 77 99 ee0000
-8 77 99 bbbbbb
-7 77 99 bbbbbb
-6 77 99 bbbbbb
-5 77 99 bbbbbb
-4 77 99 bbbbbb
-3 77 99 ee0000
-2 77 99 ee0000
-1 77 99 ee0000
-14 78 99 ffcc66
-13 78 99 ffcc66
-12 78 99 ee0000
-11 78 99 ee0000
-10 78 99 ee0000
-9 78 99 bbbbbb
-8 78 99 bbbbbb
-7 78 99 bbbbbb
-6 78 99 bbbbbb
-5 78 99 bbbbbb
-4 78 99 bbbbbb
-3 78 99 bbbbbb
-2 78 99 ee0000
-1 78 99 ee0000
-14 79 99 ffcc66
-13 79 99 ee0000
-12 79 99 ee0000
-11 79 99 ee0000
-10 79 99 ee0000
-9 79 99 bbbbbb
-8 79 99 bbbbbb
-7 79 99 bbbbbb
-6 79 99 bbbbbb
-5 79 99 bbbbbb
-4 79 99 bbbbbb
-3 79 99 bbbbbb
-2 79 99 ee0000
-1 79 99 ee0000
-9 70 100 ffcc66
-8 70 100 ffcc66
-7 70 100 ffcc66
-6 70 100 ffcc66
-5 70 100 ffcc66
-4 70 100 ffcc66
-3 70 100 ffcc66
-11 71 100 ffcc66
-10 71 100 ffcc66
-9 71 100 ffcc66
-8 71 100 ffcc66
-7 71 100 ee0000
-6 71 100 ee0000
-5 71 100 ee0000
-4 71 100 ffcc66
-3 71 100 ffcc66
-2 71 100 ffcc66
-12 72 100 ffcc66
-11 72 100 ffcc66
-10 72 100 ffcc66
-9 72 100 ee0000
-8 72 100 ee0000
-7 72 100 ee0000
-6 72 100 ee0000
-5 72 100 ee0000
-4 72 100 ee0000
-3 72 100 ee0000
-2 72 100 ffcc66
-1 72 100 ffcc66
-12 73 100 ffcc66
-11 73 100 ffcc66
-10 73 100 ee0000
-9 73 100 ee0000
-8 73 100 ee0000
-7 73 100 ee0000
-6 73 100 ee0000
-5 73 100 ee0000
-4 73 100 ee0000
-3 73 100 ee0000
-2 73 100 ee0000
-1 73 100 ffcc66
-13 74 100 ffcc66
-12 74 100 ffcc66
-11 74 100 ee0000
-10 74 100 ee0000
-9 74 100 ee0000
-8 74 100 ee0000
-7 74 100 ee0000
-6 74 100 ee0000
-5 74 100 ee0000
-4 74 100 ee0000
-3 74 100 ee0000
-2 74 100 ee0000
-1 74 100 ee0000
-13 75 100 ffcc66
-12 75 100 ffcc66
-11 75 100 ee0000
-10 75 100 ee0000
-9 75 100 ee0000
-8 75 100 ee0000
-7 75 100 ee0000
-6 75 100 ee0000
-5 75 100 ee0000
-4 75 100 ee0000
-3 75 100 ee0000
-2 75 100 ee0000
-1 75 100 ee0000
-14 76 100 ffcc66
-13 76 100 ffcc66
-12 76 100 ee0000
-11 76 100 ee0000
-10 76 100 ee0000
-9 76 100 ee0000
-8 76 100 ee0000
-7 76 100 bbbbbb
-6 76 100 bbbbbb
-5 76 100 bbbbbb
-4 76 100 ee0000
-3 76 100 ee0000
-2 76 100 ee0000
-1 76 100 ee0000
-14 77 100 ffcc66
-13 77 100 ffcc66
-12 77 100 ee0000
-11 77 100 ee0000
-10 77 100 ee0000
-9 77 100 ee0000
-8 77 100 bbbbbb
-7 77 100 bbbbbb
-6 77 100 bbbbbb
-5 77 100 bbbbbb
-4 77 100 bbbbbb
-3 77 100 ee0000
-2 77 100 ee0000
-1 77 100 ee0000
-14 78 100 ffcc66
-13 78 100 ee0000
-12 78 100 ee0000
-11 78 100 ee0000
-10 78 100 ee0000
-9 78 100 bbbbbb
-8 78 100 bbbbbb
-7 78 100 bbbbbb
-6 78 100 bbbbbb
-5 78 100 bbbbbb
-4 78 100 bbbbbb
-3 78 100 bbbbbb
-2 78 100 ee0000
-1 78 100 ee0000
-14 79 100 ffcc66
-13 79 100 ee0000
-12 79 100 ee0000
-11 79 100 ee0000
-10 79 100 ee0000
-9 79 100 bbbbbb
-8 79 100 bbbbbb
-7 79 100 bbbbbb
-6 79 100 bbbbbb
-5 79 100 bbbbbb
-4 79 100 bbbbbb
-3 79 100 bbbbbb
-2 79 100 ee0000
-1 79 100 ee0000
-8 70 101 ffcc66
-7 70 101 ffcc66
-6 70 101 ffcc66
-5 70 101 ffcc66
-4 70 101 ffcc66
-10 71 101 ffcc66
-9 71 101 ffcc66
-8 71 101 ffcc66
-7 71 101 ee0000
-6 71 101 ee0000
-5 71 101 ee0000
-4 71 101 ffcc66
-3 71 101 ffcc66
-2 71 101 ffcc66
-11 72 101 ffcc66
-10 72 101 ffcc66
-9 72 101 ee0000
-8 72 101 ee0000
-7 72 101 ee0000
-6 72 101 ee0000
-5 72 101 ee0000
-4 72 101 ee0000
-3 72 101 ee0000
-2 72 101 ffcc66
-1 72 101 ffcc66
-12 73 101 ffcc66
-11 73 101 ffcc66
-10 73 101 ee0000
-9 73 101 ee0000
-8 73 101 ee0000
-7 73 101 ee0000
-6 73 101 ee0000
-5 73 101 ee0000
-4 73 101 ee0000
-3 73 101 ee0000
-2 73 101 ee0000
-1 73 101 ffcc66
-12 74 101 ffcc66
-11 74 101 ee0000
-10 74 101 ee0000
-9 74 101 ee0000
-8 74 101 ee0000
-7 74 101 ee0000
-6 74 101 ee0000
-5 74 101 ee0000
-4 74 101 ee0000
-3 74 101 ee0000
-2 74 101 ee0000
-1 74 101 ee0000
-13 75 101 ffcc66
-12 75 101 ffcc66
-11 75 101 ee0000
-10 75 101 ee0000
-9 75 101 ee0000
-8 75 101 ee0000
-7 75 101 ee0000
-6 75 101 ee0000
-5 75 101 ee0000
-4 75 101 ee0000
-3 75 101 ee0000
-2 75 101 ee0000
-1 75 101 ee0000
-13 76 101 ffcc66
-12 76 101 ee0000
-11 76 101 ee0000
-10 76 101 ee0000
-9 76 101 ee0000
-8 76 101 ee0000
-7 76 101 bbbbbb
-6 76 101 bbbbbb
-5 76 101 bbbbbb
-4 76 101 ee0000
-3 76 101 ee0000
-2 76 101 ee0000
-1 76 101 ee0000
-14 77 101 ffcc66
-13 77 101 ffcc66
-12 77 101 ee0000
-11 77 101 ee0000
-10 77 101 ee0000
-9 77 101 ee0000
-8 77 101 bbbbbb
-7 77 101 bbbbbb
-6 77 101 bbbbbb
-5 77 101 bbbbbb
-4 77 101 bbbbbb
-3 77 101 ee0000
-2 77 101 ee0000
-1 77 101 ee0000
-14 78 101 ffcc66
-13 78 101 ffcc66
-12 78 101 ee0000
-11 78 101 ee0000
-10 78 101 ee0000
-9 78 101 bbbbbb
-8 78 101 bbbbbb
-7 78 101 bbbbbb
-6 78 101 bbbbbb
-5 78 101 bbbbbb
-4 78 101 bbbbbb
-3 78 101 bbbbbb
-2 78 101 ee0000
-1 78 101 ee0000
-14 79 101 ffcc66
-13 79 101 ffcc66
-12 79 101 ee0000
-11 79 101 ee0000
-10 79 101 ee0000
-9 79 101 bbbbbb
-8 79 101 bbbbbb
-7 79 101 bbbbbb
-6 79 101 bbbbbb
-5 79 101 bbbbbb
-4 79 101 bbbbbb
-3 79 101 bbbbbb
-2 79 101 ee0000
-1 79 101 ee0000
-8 70 102 ffcc66
-7 70 102 ffcc66
-6 70 102 ffcc66
-5 70 102 ffcc66
-4 70 102 ffcc66
-3 70 102 ffcc66
-10 71 102 ffcc66
-9 71 102 ffcc66
-8 71 102 ffcc66
-7 71 102 ee0000
-6 71 102 ee0000
-5 71 102 ee0000
-4 71 102 ffcc66
-3 71 102 ffcc66
-2 71 102 ffcc66
-11 72 102 ffcc66
-10 72 102 ffcc66
-9 72 102 ee0000
-8 72 102 ee0000
-7 72 102 ee0000
-6 72 102 ee0000
-5 72 102 ee0000
-4 72 102 ee0000
-3 72 102 ee0000
-2 72 102 ffcc66
-1 72 102 ffcc66
-12 73 102 ffcc66
-11 73 102 ffcc66
-10 73 102 ee0000
-9 73 102 ee0000
-8 73 102 ee0000
-7 73 102 ee0000
-6 73 102 ee0000
-5 73 102 ee0000
-4 73 102 ee0000
-3 73 102 ee0000
-2 73 102 ee0000
-1 73 102 ffcc66
-12 74 102 ffcc66
-11 74 102 ffcc66
-10 74 102 ee0000
-9 74 102 ee0000
-8 74 102 ee0000
-7 74 102 ee0000
-6 74 102 ee0000
-5 74 102 ee0000
-4 74 102 ee0000
-3 74 102 ee0000
-2 74 102 ee0000
-1 74 102 ee0000
-13 75 102 ffcc66
-12 75 102 ffcc66
-11 75 102 ee0000
-10 75 102 ee0000
-9 75 102 ee0000
-8 75 102 ee0000
-7 75 102 ee0000
-6 75 102 ee0000
-5 75 102 ee0000
-4 75 102 ee0000
-3 75 102 ee0000
-2 75 102 ee0000
-1 75 102 ee0000
-13 76 102 ffcc66
-12 76 102 ffcc66
-11 76 102 ee0000
-10 76 102 ee0000
-9 76 102 ee0000
-8 76 102 ee0000
-7 76 102 bbbbbb
-6 76 102 bbbbbb
-5 76 102 bbbbbb
-4 76 102 ee0000
-3 76 102 ee0000
-2 76 102 ee0000
-1 76 102 ee0000
-13 77 102 ffcc66
-12 77 102 ee0000
-11 77 102 ee0000
-10 77 102 ee0000
-9 77 102 ee0000
-8 77 102 bbbbbb
-7 77 102 bbbbbb
-6 77 102 bbbbbb
-5 77 102 bbbbbb
-4 77 102 bbbbbb
-3 77 102 ee0000
-2 77 102 ee0000
-1 77 102 ee0000
-13 78 102 ffcc66
-12 78 102 ee0000
-11 78 102 ee0000
-10 78 102 ee0000
-9 78 102 bbbbbb
-8 78 102 bbbbbb
-7 78 102 bbbbbb
-6 78 102 bbbbbb
-5 78 102 bbbbbb
-4 78 102 bbbbbb
-3 78 102 bbbbbb
-2 78 102 ee0000
-1 78 102 ee0000
-14 79 102 ffcc66
-13 79 102 ffcc66
-12 79 102 ee0000
-11 79 102 ee0000
-10 79 102 ee0000
-9 79 102 bbbbbb
-8 79 102 bbbbbb
-7 79 102 bbbbbb
-6 79 102 bbbbbb
-5 79 102 bbbbbb
-4 79 102 bbbbbb
-3 79 102 bbbbbb
-2 79 102 ee0000
-1 79 102 ee0000
-7 69 103 ffcc66
-6 69 103 ffcc66
-5 69 103 ffcc66
-4 69 103 ffcc66
-9 70 103 ffcc66
-8 70 103 ffcc66
-7 70 103 ffcc66
-6 70 103 ffcc66
-5 70 103 ffcc66
-4 70 103 ffcc66
-3 70 103 ffcc66
-2 70 103 ffcc66
-10 71 103 ffcc66
-9 71 103 ffcc66
-8 71 103 ffcc66
-7 71 103 ee0000
-6 71 103 ee0000
-5 71 103 ee0000
-4 71 103 ee0000
-3 71 103 ffcc66
-2 71 103 ffcc66
-1 71 103 ffcc66
-11 72 103 ffcc66
-10 72 103 ffcc66
-9 72 103 ee0000
-8 72 103 ee0000
-7 72 103 ee0000
-6 72 103 ee0000
-5 72 103 ee0000
-4 72 103 ee0000
-3 72 103 ee0000
-2 72 103 ffcc66
-1 72 103 ffcc66
-11 73 103 ffcc66
-10 73 103 ee0000
-9 73 103 ee0000
-8 73 103 ee0000
-7 73 103 ee0000
-6 73 103 ee0000
-5 73 103 ee0000
-4 73 103 ee0000
-3 73 103 ee0000
-2 73 103 ee0000
-1 73 103 ffcc66
-12 74 103 ffcc66
-11 74 103 ffcc66
-10 74 103 ee0000
-9 74 103 ee0000
-8 74 103 ee0000
-7 74 103 ee0000
-6 74 103 ee0000
-5 74 103 ee0000
-4 74 103 ee0000
-3 74 103 ee0000
-2 74 103 ee0000
-1 74 103 ee0000
-12 75 103 ffcc66
-11 75 103 ee0000
-10 75 103 ee0000
-9 75 103 ee0000
-8 75 103 ee0000
-7 75 103 ee0000
-6 75 103 ee0000
-5 75 103 ee0000
-4 75 103 ee0000
-3 75 103 ee0000
-2 75 103 ee0000
-1 75 103 ee0000
-13 76 103 ffcc66
-12 76 103 ffcc66
-11 76 103 ee0000
-10 76 103 ee0000
-9 76 103 ee0000
-8 76 103 ee0000
-7 76 103 ee0000
-6 76 103 ee0000
-5 76 103 ee0000
-4 76 103 ee0000
-3 76 103 ee0000
-2 76 103 ee0000
-1 76 103 ee0000
-13 77 103 ffcc66
-12 77 103 ffcc66
-11 77 103 ee0000
-10 77 103 ee0000
-9 77 103 ee0000
-8 77 103 ee0000
-7 77 103 bbbbbb
-6 77 103 bbbbbb
-5 77 103 bbbbbb
-4 77 103 ee0000
-3 77 103 ee0000
-2 77 103 ee0000
-1 77 103 ee0000
-13 78 103 ffcc66
-12 78 103 ee0000
-11 78 103 ee0000
-10 78 103 ee0000
-9 78 103 ee0000
-8 78 103 bbbbbb
-7 78 103 bbbbbb
-6 78 103 bbbbbb
-5 78 103 bbbbbb
-4 78 103 bbbbbb
-3 78 103 ee0000
-2 78 103 ee0000
-1 78 103 ee0000
-13 79 103 ffcc66
-12 79 103 ee0000
-11 79 103 ee0000
-10 79 103 ee0000
-9 79 103 ee0000
-8 79 103 bbbbbb
-7 79 103 bbbbbb
-6 79 103 bbbbbb
-5 79 103 bbbbbb
-4 79 103 bbbbbb
-3 79 103 ee0000
-2 79 103 ee0000
-1 79 103 bbbbbb
-8 69 104 ffcc66
-7 69 104 ffcc66
-6 69 104 ffcc66
-5 69 104 ffcc66
-4 69 104 ffcc66
-3 69 104 ffcc66
-2 69 104 ffcc66
-9 70 104 ffcc66
-8 70 104 ffcc66
-7 70 104 ffcc66
-6 70 104 ee0000
-5 70 104 ee0000
-4 70 104 ffcc66
-3 70 104 ffcc66
-2 70 104 ffcc66
-1 70 104 ffcc66
-10 71 104 ffcc66
-9 71 104 ffcc66
-8 71 104 ee0000
-7 71 104 ee0000
-6 71 104 ee0000
-5 71 104 ee0000
-4 71 104 ee0000
-3 71 104 ee0000
-2 71 104 ffcc66
-1 71 104 ffcc66
-11 72 104 ffcc66
-10 72 104 ffcc66
-9 72 104 ee0000
-8 72 104 ee0000
-7 72 104 ee0000
-6 72 104 ee0000
-5 72 104 ee0000
-4 72 104 ee0000
-3 72 104 ee0000
-2 72 104 ee0000
-1 72 104 ffcc66
-11 73 104 ffcc66
-10 73 104 ee0000
-9 73 104 ee0000
-8 73 104 ee0000
-7 73 104 ee0000
-6 73 104 ee0000
-5 73 104 ee0000
-4 73 104 ee0000
-3 73 104 ee0000
-2 73 104 ee0000
-1 73 104 ee0000
-12 74 104 ffcc66
-11 74 104 ffcc66
-10 74 104 ee0000
-9 74 104 ee0000
-8 74 104 ee0000
-7 74 104 ee0000
-6 74 104 ee0000
-5 74 104 ee0000
-4 74 104 ee0000
-3 74 104 ee0000
-2 74 104 ee0000
-1 74 104 ee0000
-12 75 104 ffcc66
-11 75 104 ee0000
-10 75 104 ee0000
-9 75 104 ee0000
-8 75 104 ee0000
-7 75 104 ee0000
-6 75 104 ee0000
-5 75 104 ee0000
-4 75 104 ee0000
-3 75 104 ee0000
-2 75 104 ee0000
-1 75 104 ee0000
-12 76 104 ffcc66
-11 76 104 ee0000
-10 76 104 ee0000
-9 76 104 ee0000
-8 76 104 ee0000
-7 76 104 ee0000
-6 76 104 ee0000
-5 76 104 ee0000
-4 76 104 ee0000
-3 76 104 ee0000
-2 76 104 ee0000
-1 76 104 ee0000
-13 77 104 ffcc66
-12 77 104 ffcc66
-11 77 104 ee0000
-10 77 104 ee0000
-9 77 104 ee0000
-8 77 104 ee0000
-7 77 104 ee0000
-6 77 104 ee0000
-5 77 104 ee0000
-4 77 104 ee0000
-3 77 104 ee0000
-2 77 104 ee0000
-1 77 104 ee0000
-13 78 104 ffcc66
-12 78 104 ee0000
-11 78 104 ee0000
-10 78 104 ee0000
-9 78 104 ee0000
-8 78 104 ee0000
-7 78 104 bbbbbb
-6 78 104 bbbbbb
-5 78 104 bbbbbb
-4 78 104 ee0000
-3 78 104 ee0000
-2 78 104 ee0000
-1 78 104 ee0000
-13 79 104 ffcc66
-12 79 104 ee0000
-11 79 104 ee0000
-10 79 104 ee0000
-9 79 104 ee0000
-8 79 104 ee0000
-7 79 104 bbbbbb
-6 79 104 bbbbbb
-5 79 104 bbbbbb
-4 79 104 ee0000
-3 79 104 ee0000
-2 79 104 ee0000
-1 79 104 ee0000
-6 68 105 ffcc66
-5 68 105 ffcc66
-4 68 105 ffcc66
-3 68 105 ffcc66
-8 69 105 ffcc66
-7 69 105 ffcc66
-6 69 105 ffcc66
-5 69 105 ffcc66
-4 69 105 ffcc66
-3 69 105 ffcc66
-2 69 105 ffcc66
-1 69 105 ffcc66
-9 70 105 ffcc66
-8 70 105 ffcc66
-7 70 105 ee0000
-6 70 105 ee0000
-5 70 105 ee0000
-4 70 105 ee0000
-3 70 105 ee0000
-2 70 105 ffcc66
-1 70 105 ffcc66
-10 71 105 ffcc66
-9 71 105 ffcc66
-8 71 105 ee0000
-7 71 105 ee0000
-6 71 105 ee0000
-5 71 105 ee0000
-4 71 105 ee0000
-3 71 105 ee0000
-2 71 105 ee0000
-1 71 105 ffcc66
-11 72 105 ffcc66
-10 72 105 ffcc66
-9 72 105 ee0000
-8 72 105 ee0000
-7 72 105 ee0000
-6 72 105 ee0000
-5 72 105 ee0000
-4 72 105 ee0000
-3 72 105 ee0000
-2 72 105 ee0000
-1 72 105 ee0000
-11 73 105 ffcc66
-10 73 105 ffcc66
-9 73 105 ee0000
-8 73 105 ee0000
-7 73 105 ee0000
-6 73 105 ee0000
-5 73 105 ee0000
-4 73 105 ee0000
-3 73 105 ee0000
-2 73 105 ee0000
-1 73 105 ee0000
-12 74 105 ffcc66
-11 74 105 ffcc66
-10 74 105 ee0000
-9 74 105 ee0000
-8 74 105 ee0000
-7 74 105 ee0000
-6 74 105 ee0000
-5 74 105 ee0000
-4 74 105 ee0000
-3 74 105 ee0000
-2 74 105 ee0000
-1 74 105 ee0000
-12 75 105 ffcc66
-11 75 105 ffcc66
-10 75 105 ee0000
-9 75 105 ee0000
-8 75 105 ee0000
-7 75 105 ee0000
-6 75 105 ee0000
-5 75 105 ee0000
-4 75 105 ee0000
-3 75 105 ee0000
-2 75 105 ee0000
-1 75 105 ee0000
-12 76 105 ffcc66
-11 76 105 ee0000
-10 76 105 ee0000
-9 76 105 ee0000
-8 76 105 ee0000
-7 76 105 ee0000
-6 76 105 ee0000
-5 76 105 ee0000
-4 76 105 ee0000
-3 76 105 ee0000
-2 76 105 ee0000
-1 76 105 ee0000
-13 77 105 ffcc66
-12 77 105 ffcc66
-11 77 105 ee0000
-10 77 105 ee0000
-9 77 105 ee0000
-8 77 105 ee0000
-7 77 105 ee0000
-6 77 105 ee0000
-5 77 105 ee0000
-4 77 105 ee0000
-3 77 105 ee0000
-2 77 105 ee0000
-1 77 105 ee0000
-13 78 105 ffcc66
-12 78 105 ffcc66
-11 78 105 ee0000
-10 78 105 ee0000
-9 78 105 ee0000
-8 78 105 bbbbbb
-7 78 105 bbbbbb
-6 78 105 ee0000
-5 78 105 ee0000
-4 78 105 ee0000
-3 78 105 ee0000
-2 78 105 ee0000
-1 78 105 ee0000
-13 79 105 ffcc66
-12 79 105 ee0000
-11 79 105 ee0000
-10 79 105 ee0000
-9 79 105 ee0000
-8 79 105 bbbbbb
-7 79 105 bbbbbb
-6 79 105 ee0000
-5 79 105 ee0000
-4 79 105 ee0000
-3 79 105 ee0000
-2 79 105 ee0000
-1 79 105 33ffff
-7 68 106 ffcc66
-6 68 106 ffcc66
-5 68 106 ffcc66
-4 68 106 ffcc66
-3 68 106 ffcc66
-2 68 106 ffcc66
-8 69 106 ffcc66
-7 69 106 ffcc66
-6 69 106 ffcc66
-5 69 106 ee0000
-4 69 106 ee0000
-3 69 106 ffcc66
-2 69 106 ffcc66
-1 69 106 ffcc66
-9 70 106 ffcc66
-8 70 106 ffcc66
-7 70 106 ee0000
-6 70 106 ee0000
-5 70 106 ee0000
-4 70 106 ee0000
-3 70 106 ee0000
-2 70 106 ee0000
-1 70 106 ffcc66
-10 71 106 ffcc66
-9 71 106 ffcc66
-8 71 106 ee0000
-7 71 106 ee0000
-6 71 106 ee0000
-5 71 106 ee0000
-4 71 106 ee0000
-3 71 106 ee0000
-2 71 106 ee0000
-1 71 106 ee0000
-10 72 106 ffcc66
-9 72 106 ee0000
-8 72 106 ee0000
-7 72 106 ee0000
-6 72 106 ee0000
-5 72 106 ee0000
-4 72 106 ee0000
-3 72 106 ee0000
-2 72 106 ee0000
-1 72 106 ee0000
-11 73 106 ffcc66
-10 73 106 ffcc66
-9 73 106 ee0000
-8 73 106 ee0000
-7 73 106 ee0000
-6 73 106 ee0000
-5 73 106 ee0000
-4 73 106 ee0000
-3 73 106 ee0000
-2 73 106 ee0000
-1 73 106 ee0000
-11 74 106 ffcc66
-10 74 106 ee0000
-9 74 106 ee0000
-8 74 106 ee0000
-7 74 106 ee0000
-6 74 106 ee0000
-5 74 106 ee0000
-4 74 106 ee0000
-3 74 106 ee0000
-2 74 106 ee0000
-1 74 106 ee0000
-12 75 106 ffcc66
-11 75 106 ffcc66
-10 75 106 ee0000
-9 75 106 ee0000
-8 75 106 ee0000
-7 75 106 ee0000
-6 75 106 ee0000
-5 75 106 ee0000
-4 75 106 ee0000
-3 75 106 ee0000
-2 75 106 ee0000
-1 75 106 ee0000
-12 76 106 ffcc66
-11 76 106 ee0000
-10 76 106 ee0000
-9 76 106 ee0000
-8 76 106 ee0000
-7 76 106 ee0000
-6 76 106 ee0000
-5 76 106 ee0000
-4 76 106 ee0000
-3 76 106 ee0000
-2 76 106 ee0000
-1 76 106 ee0000
-12 77 106 ffcc66
-11 77 106 ee0000
-10 77 106 bbbbbb
-9 77 106 bbbbbb
-8 77 106 ee0000
-7 77 106 ee0000
-6 77 106 ee0000
-5 77 106 ee0000
-4 77 106 ee0000
-3 77 106 ee0000
-2 77 106 ee0000
-1 77 106 ee0000
-13 78 106 ffcc66
-12 78 106 ffcc66
-11 78 106 ee0000
-10 78 106 bbbbbb
-9 78 106 bbbbbb
-8 78 106 bbbbbb
-7 78 106 ee0000
-6 78 106 ee0000
-5 78 106 ee0000
-4 78 106 ee0000
-3 78 106 ee0000
-2 78 106 ee0000
-1 78 106 ee0000
-13 79 106 ffcc66
-12 79 106 ffcc66
-11 79 106 ee0000
-10 79 106 bbbbbb
-9 79 106 bbbbbb
-8 79 106 bbbbbb
-7 79 106 ee0000
-6 79 106 ee0000
-5 79 106 ee0000
-4 79 106 ee0000
-3 79 106 ee0000
-2 79 106 ee0000
-1 79 106 33ffff
-7 68 107 ffcc66
-6 68 107 ffcc66
-5 68 107 ffcc66
-4 68 107 ffcc66
-3 68 107 ffcc66
-2 68 107 ffcc66
-8 69 107 ffcc66
-7 69 107 ffcc66
-6 69 107 ee0000
-5 69 107 ee0000
-4 69 107 ee0000
-3 69 107 ee0000
-2 69 107 ffcc66
-1 69 107 ffcc66
-9 70 107 ffcc66
-8 70 107 ffcc66
-7 70 107 ee0000
-6 70 107 ee0000
-5 70 107 ee0000
-4 70 107 ee0000
-3 70 107 ee0000
-2 70 107 ee0000
-1 70 107 ffcc66
-10 71 107 ffcc66
-9 71 107 ffcc66
-8 71 107 ee0000
-7 71 107 ee0000
-6 71 107 ee0000
-5 71 107 ee0000
-4 71 107 ee0000
-3 71 107 ee0000
-2 71 107 ee0000
-1 71 107 ee0000
-10 72 107 ffcc66
-9 72 107 ee0000
-8 72 107 ee0000
-7 72 107 ee0000
-6 72 107 ee0000
-5 72 107 ee0000
-4 72 107 ee0000
-3 72 107 ee0000
-2 72 107 ee0000
-1 72 107 ee0000
-11 73 107 ffcc66
-10 73 107 ffcc66
-9 73 107 ee0000
-8 73 107 ee0000
-7 73 107 ee0000
-6 73 107 ee0000
-5 73 107 ee0000
-4 73 107 ee0000
-3 73 107 ee0000
-2 73 107 ee0000
-1 73 107 ee0000
-11 74 107 ffcc66
-10 74 107 ee0000
-9 74 107 ee0000
-8 74 107 ee0000
-7 74 107 ee0000
-6 74 107 ee0000
-5 74 107 ee0000
-4 74 107 ee0000
-3 74 107 ee0000
-2 74 107 ee0000
-1 74 107 ee0000
-12 75 107 ffcc66
-11 75 107 ffcc66
-10 75 107 ee0000
-9 75 107 ee0000
-8 75 107 ee0000
-7 75 107 ee0000
-6 75 107 ee0000
-5 75 107 ee0000
-4 75 107 ee0000
-3 75 107 ee0000
-2 75 107 ee0000
-1 75 107 ee0000
-12 76 107 ffcc66
-11 76 107 ffcc66
-10 76 107 bbbbbb
-9 76 107 bbbbbb
-8 76 107 ee0000
-7 76 107 ee0000
-6 76 107 ee0000
-5 76 107 ee0000
-4 76 107 ee0000
-3 76 107 ee0000
-2 76 107 ee0000
-1 76 107 ee0000
-12 77 107 ffcc66
-11 77 107 bbbbbb
-10 77 107 bbbbbb
-9 77 107 bbbbbb
-8 77 107 ee0000
-7 77 107 ee0000
-6 77 107 ff6633
-5 77 107 ff6633
-4 77 107 ee0000
-3 77 107 ee0000
-2 77 107 ee0000
-1 77 107 ee0000
-12 78 107 ffcc66
-11 78 107 bbbbbb
-10 78 107 bbbbbb
-9 78 107 bbbbbb
-8 78 107 ee0000
-7 78 107 ee0000
-6 78 107 ff6633
-5 78 107 ff6633
-4 78 107 ee0000
-3 78 107 ee0000
-2 78 107 ee0000
-1 78 107 ee0000
-12 79 107 ffcc66
-11 79 107 bbbbbb
-10 79 107 bbbbbb
-9 79 107 bbbbbb
-8 79 107 ee0000
-7 79 107 ee0000
-6 79 107 ff6633
-5 79 107 ff6633
-4 79 107 ee0000
-3 79 107 ee0000
-2 79 107 ee0000
-1 79 107 33ffff
-7 68 108 ffcc66
-6 68 108 ffcc66
-5 68 108 ffcc66
-4 68 108 ffcc66
-3 68 108 ffcc66
-2 68 108 ffcc66
-1 68 108 ffcc66
-8 69 108 ffcc66
-7 69 108 ffcc66
-6 69 108 ee0000
-5 69 108 ee0000
-4 69 108 ee0000
-3 69 108 ee0000
-2 69 108 ffcc66
-1 69 108 ffcc66
-9 70 108 ffcc66
-8 70 108 ffcc66
-7 70 108 ee0000
-6 70 108 ee0000
-5 70 108 ee0000
-4 70 108 ee0000
-3 70 108 ee0000
-2 70 108 ee0000
-1 70 108 ee0000
-10 71 108 ffcc66
-9 71 108 ffcc66
-8 71 108 ee0000
-7 71 108 ee0000
-6 71 108 ee0000
-5 71 108 ee0000
-4 71 108 ee0000
-3 71 108 ee0000
-2 71 108 ee0000
-1 71 108 ee0000
-10 72 108 ffcc66
-9 72 108 ee0000
-8 72 108 ee0000
-7 72 108 ee0000
-6 72 108 ee0000
-5 72 108 ee0000
-4 72 108 cc0066
-3 72 108 ee0000
-2 72 108 ee0000
-1 72 108 ee0000
-11 73 108 ffcc66
-10 73 108 ffcc66
-9 73 108 ee0000
-8 73 108 ee0000
-7 73 108 ee0000
-6 73 108 ee0000
-5 73 108 ee0000
-4 73 108 cc0066
-3 73 108 ee0000
-2 73 108 ee0000
-1 73 108 ee0000
-11 74 108 ffcc66
-10 74 108 ee0000
-9 74 108 ee0000
-8 74 108 ee0000
-7 74 108 ee0000
-6 74 108 ee0000
-5 74 108 ee0000
-4 74 108 ee0000
-3 74 108 ee0000
-2 74 108 ee0000
-1 74 108 ee0000
-11 75 108 ffcc66
-10 75 108 bbbbbb
-9 75 108 ee0000
-8 75 108 ee0000
-7 75 108 ee0000
-6 75 108 ee0000
-5 75 108 ee0000
-4 75 108 ee0000
-3 75 108 ee0000
-2 75 108 ee0000
-1 75 108 ee0000
-12 76 108 ffcc66
-11 76 108 ffcc66
-10 76 108 bbbbbb
-9 76 108 ee0000
-8 76 108 ee0000
-7 76 108 ee0000
-6 76 108 ff6633
-5 76 108 ff6633
-4 76 108 ee0000
-3 76 108 ee0000
-2 76 108 ee0000
-1 76 108 ee0000
-12 77 108 ffcc66
-11 77 108 bbbbbb
-10 77 108 bbbbbb
-9 77 108 ee0000
-8 77 108 cc0066
-7 77 108 cc0066
-6 77 108 ff6633
-5 77 108 ff6633
-4 77 108 ee0000
-3 77 108 ee0000
-2 77 108 ee0000
-1 77 108 ee0000
-12 78 108 ffcc66
-11 78 108 bbbbbb
-10 78 108 bbbbbb
-9 78 108 ee0000
-8 78 108 cc0066
-7 78 108 cc0066
-6 78 108 ff6633
-5 78 108 ff6633
-4 78 108 ee0000
-3 78 108 ee0000
-2 78 108 ee0000
-1 78 108 ee0000
-12 79 108 ffcc66
-11 79 108 bbbbbb
-10 79 108 bbbbbb
-9 79 108 ee0000
-8 79 108 cc0066
-7 79 108 cc0066
-6 79 108 ff6633
-5 79 108 ff6633
-4 79 108 ee0000
-3 79 108 ee0000
-2 79 108 ee0000
-1 79 108 33ffff
-7 68 109 ffcc66
-6 68 109 ffcc66
-5 68 109 ffcc66
-4 68 109 ffcc66
-3 68 109 ffcc66
-2 68 109 ffcc66
-1 68 109 ffcc66
-8 69 109 ffcc66
-7 69 109 ffcc66
-6 69 109 ee0000
-5 69 109 ee0000
-4 69 109 ee0000
-3 69 109 ee0000
-2 69 109 ee0000
-1 69 109 ffcc66
-9 70 109 ffcc66
-8 70 109 ffcc66
-7 70 109 ee0000
-6 70 109 ee0000
-5 70 109 ee0000
-4 70 109 ee0000
-3 70 109 ee0000
-2 70 109 ee0000
-1 70 109 ee0000
-10 71 109 ffcc66
-9 71 109 ffcc66
-8 71 109 ee0000
-7 71 109 ee0000
-6 71 109 ee0000
-5 71 109 ee0000
-4 71 109 ee0000
-3 71 109 ee0000
-2 71 109 ee0000
-1 71 109 ee0000
-10 72 109 ffcc66
-9 72 109 ffcc66
-8 72 109 ee0000
-7 72 109 ee0000
-6 72 109 ee0000
-4 72 109 cc0066
-3 72 109 ee0000
-2 72 109 ee0000
-1 72 109 ee0000
-11 73 109 ffcc66
-10 73 109 ffcc66
-9 73 109 ee0000
-8 73 109 ee0000
-7 73 109 ee0000
-6 73 109 ee0000
-5 73 109 ee0000
-4 73 109 cc0066
-3 73 109 ee0000
-2 73 109 ee0000
-1 73 109 ee0000
-11 74 109 ffcc66
-10 74 109 bbbbbb
-9 74 109 ee0000
-8 74 109 ee0000
-7 74 109 ee0000
-6 74 109 ee0000
-5 74 109 cc0066
-4 74 109 cc0066
-3 74 109 ee0000
-2 74 109 ee0000
-1 74 109 ee0000
-11 75 109 ffcc66
-10 75 109 bbbbbb
-9 75 109 ee0000
-8 75 109 ee0000
-7 75 109 ee0000
-6 75 109 ee0000
-5 75 109 cc0066
-4 75 109 cc0066
-3 75 109 ee0000
-2 75 109 0000ff
-12 76 109 ffcc66
-11 76 109 ffcc66
-10 76 109 bbbbbb
-9 76 109 ee0000
-8 76 109 cc0066
-7 76 109 cc0066
-6 76 109 ff6633
-5 76 109 ff6633
-4 76 109 ff6633
-3 76 109 ff6633
-2 76 109 0000ff
-1 76 109 0000ff
-12 77 109 ffcc66
-11 77 109 ffcc66
-10 77 109 bbbbbb
-9 77 109 ee0000
-8 77 109 cc0066
-7 77 109 cc0066
-6 77 109 ff6633
-5 77 109 ff6633
-4 77 109 ff6633
-3 77 109 ff6633
-2 77 109 ee0000
-1 77 109 0000ff
-12 78 109 ffcc66
-11 78 109 bbbbbb
-10 78 109 bbbbbb
-9 78 109 ee0000
-8 78 109 ee0000
-7 78 109 ee0000
-6 78 109 ee0000
-5 78 109 ee0000
-4 78 109 ee0000
-3 78 109 cc0066
-2 78 109 cc0066
-1 78 109 0000ff
-12 79 109 ffcc66
-11 79 109 bbbbbb
-10 79 109 bbbbbb
-9 79 109 ee0000
-8 79 109 ee0000
-7 79 109 ee0000
-6 79 109 ee0000
-5 79 109 cc0066
-4 79 109 cc0066
-3 79 109 cc0066
-2 79 109 cc0066
-1 79 109 ee0000
-7 68 110 ffcc66
-6 68 110 ffcc66
-5 68 110 ffcc66
-4 68 110 ffcc66
-3 68 110 ffcc66
-2 68 110 ffcc66
-1 68 110 ffcc66
-8 69 110 ffcc66
-7 69 110 ffcc66
-6 69 110 ffcc66
-5 69 110 ee0000
-4 69 110 ee0000
-3 69 110 ee0000
-2 69 110 ee0000
-1 69 110 ffcc66
-9 70 110 ffcc66
-8 70 110 ffcc66
-7 70 110 ee0000
-6 70 110 ee0000
-5 70 110 ee0000
-4 70 110 ee0000
-3 70 110 ee0000
-2 70 110 ee0000
-1 70 110 ee0000
-9 71 110 ffcc66
-8 71 110 ee0000
-7 71 110 ee0000
-6 71 110 ee0000
-5 71 110 ee0000
-4 71 110 ee0000
-3 71 110 ee0000
-2 71 110 ee0000
-1 71 110 ee0000
-10 72 110 ffcc66
-9 72 110 ffcc66
-8 72 110 ee0000
-7 72 110 ee0000
-6 72 110 ee0000
-5 72 110 ee0000
-4 72 110 cc0066
-3 72 110 ee0000
-2 72 110 ee0000
-1 72 110 ee0000
-11 73 110 ffcc66
-10 73 110 ffcc66
-9 73 110 ee0000
-8 73 110 ee0000
-7 73 110 ee0000
-6 73 110 ee0000
-5 73 110 ee0000
-4 73 110 cc0066
-3 73 110 ee0000
-2 73 110 ee0000
-1 73 110 ee0000
-11 74 110 ffcc66
-10 74 110 ffcc66
-9 74 110 bbbbbb
-8 74 110 ee0000
-7 74 110 ee0000
-6 74 110 ee0000
-5 74 110 ee0000
-4 74 110 cc0066
-3 74 110 ee0000
-2 74 110 0000ff
-1 74 110 ee0000
-11 75 110 ffcc66
-10 75 110 bbbbbb
-9 75 110 bbbbbb
-8 75 110 ee0000
-7 75 110 ee0000
-6 75 110 ee0000
-5 75 110 ee0000
-4 75 110 ee0000
-3 75 110 ee0000
-2 75 110 0000ff
-1 75 110 ff6633
-11 76 110 ffcc66
-10 76 110 bbbbbb
-9 76 110 ee0000
-8 76 110 cc0066
-7 76 110 cc0066
-6 76 110 cc0066
-5 76 110 cc0066
-4 76 110 ff6633
-3 76 110 ff6633
-2 76 110 ff6633
-1 76 110 ff6633
-12 77 110 ffcc66
-11 77 110 ffcc66
-10 77 110 bbbbbb
-9 77 110 ee0000
-8 77 110 cc0066
-7 77 110 cc0066
-6 77 110 cc0066
-5 77 110 cc0066
-4 77 110 ff6633
-3 77 110 ff6633
-2 77 110 ff6633
-1 77 110 ee0000
-12 78 110 ffcc66
-11 78 110 bbbbbb
-10 78 110 bbbbbb
-9 78 110 ee0000
-8 78 110 ee0000
-7 78 110 ee0000
-6 78 110 ee0000
-5 78 110 ee0000
-4 78 110 ee0000
-3 78 110 cc0066
-2 78 110 cc0066
-1 78 110 ee0000
-12 79 110 ffcc66
-11 79 110 bbbbbb
-10 79 110 bbbbbb
-9 79 110 ee0000
-8 79 110 ee0000
-7 79 110 ee0000
-6 79 110 ee0000
-5 79 110 ee0000
-4 79 110 ee0000
-3 79 110 ee0000
-2 79 110 ee0000
-1 79 110 ee0000
-6 68 111 ffcc66
-5 68 111 ffcc66
-4 68 111 ffcc66
-3 68 111 ffcc66
-2 68 111 ffcc66
-1 68 111 ffcc66
-8 69 111 ffcc66
-7 69 111 ffcc66
-6 69 111 ffcc66
-5 69 111 bbbbbb
-4 69 111 bbbbbb
-3 69 111 bbbbbb
-2 69 111 ffcc66
-1 69 111 ffcc66
-9 70 111 ffcc66
-8 70 111 ffcc66
-7 70 111 ffcc66
-6 70 111 bbbbbb
-5 70 111 bbbbbb
-4 70 111 bbbbbb
-3 70 111 bbbbbb
-2 70 111 bbbbbb
-9 71 111 ffcc66
-8 71 111 ffcc66
-7 71 111 bbbbbb
-6 71 111 bbbbbb
-5 71 111 ee0000
-4 71 111 ee0000
-3 71 111 bbbbbb
-2 71 111 bbbbbb
-1 71 111 bbbbbb
-10 72 111 ffcc66
-9 72 111 ffcc66
-8 72 111 bbbbbb
-7 72 111 bbbbbb
-6 72 111 bbbbbb
-5 72 111 ee0000
-4 72 111 cc0066
-3 72 111 ee0000
-2 72 111 ee0000
-1 72 111 bbbbbb
-10 73 111 ffcc66
-9 73 111 bbbbbb
-8 73 111 bbbbbb
-7 73 111 bbbbbb
-6 73 111 bbbbbb
-5 73 111 ee0000
-4 73 111 ee0000
-3 73 111 ee0000
-2 73 111 0000ff
-1 73 111 ee0000
-11 74 111 ffcc66
-10 74 111 ffcc66
-9 74 111 bbbbbb
-8 74 111 bbbbbb
-7 74 111 ee0000
-6 74 111 ee0000
-5 74 111 ee0000
-4 74 111 ee0000
-3 74 111 ee0000
-2 74 111 0000ff
-1 74 111 ee0000
-11 75 111 ffcc66
-10 75 111 bbbbbb
-9 75 111 bbbbbb
-8 75 111 ee0000
-7 75 111 ee0000
-6 75 111 ee0000
-5 75 111 ee0000
-4 75 111 ee0000
-3 75 111 ee0000
-2 75 111 ff6633
-1 75 111 ff6633
-11 76 111 ffcc66
-10 76 111 bbbbbb
-9 76 111 bbbbbb
-8 76 111 ee0000
-7 76 111 ee0000
-6 76 111 ee0000
-5 76 111 ee0000
-4 76 111 ee0000
-3 76 111 ff6633
-2 76 111 ff6633
-1 76 111 ff6633
-12 77 111 ffcc66
-11 77 111 ffcc66
-10 77 111 bbbbbb
-9 77 111 bbbbbb
-8 77 111 ee0000
-7 77 111 ee0000
-6 77 111 ee0000
-5 77 111 ee0000
-4 77 111 ee0000
-3 77 111 ff6633
-2 77 111 ff6633
-1 77 111 ee0000
-12 78 111 ffcc66
-11 78 111 ffcc66
-10 78 111 bbbbbb
-9 78 111 bbbbbb
-8 78 111 ee0000
-7 78 111 ee0000
-6 78 111 ee0000
-5 78 111 ee0000
-4 78 111 ee0000
-3 78 111 cc0066
-2 78 111 cc0066
-1 78 111 ee0000
-12 79 111 ffcc66
-11 79 111 bbbbbb
-10 79 111 bbbbbb
-9 79 111 bbbbbb
-8 79 111 ee0000
-7 79 111 ee0000
-6 79 111 ee0000
-5 79 111 ee0000
-4 79 111 ee0000
-3 79 111 ee0000
-2 79 111 ee0000
-1 79 111 ee0000
0 79 97 ffcc66
1 79 97 ffcc66
2 79 97 ffcc66
3 79 97 ffcc66
6 70 98 ffcc66
7 70 98 ffcc66
8 70 98 ffcc66
9 70 98 ffcc66
4 71 98 ffcc66
5 71 98 ffcc66
6 71 98 ffcc66
7 71 98 ffcc66
8 71 98 ffcc66
9 71 98 ffcc66
10 71 98 ffcc66
11 71 98 ffcc66
4 72 98 ffcc66
5 72 98 ffcc66
6 72 98 ffcc66
7 72 98 ffcc66
8 72 98 ffcc66
9 72 98 ffcc66
10 72 98 ffcc66
11 72 98 ffcc66
12 72 98 ffcc66
0 73 98 ffcc66
3 73 98 ffcc66
4 73 98 ffcc66
5 73 98 ffcc66
6 73 98 ffcc66
7 73 98 ffcc66
8 73 98 ffcc66
9 73 98 ffcc66
10 73 98 ffcc66
11 73 98 ffcc66
12 73 98 ffcc66
0 74 98 ffcc66
2 74 98 ffcc66
3 74 98 ffcc66
4 74 98 ffcc66
5 74 98 ffcc66
6 74 98 ffcc66
7 74 98 ffcc66
8 74 98 ffcc66
9 74 98 ffcc66
10 74 98 ffcc66
11 74 98 ffcc66
12 74 98 ffcc66
13 74 98 ffcc66
0 75 98 ffcc66
1 75 98 ffcc66
2 75 98 ffcc66
3 75 98 ffcc66
4 75 98 ffcc66
5 75 98 ffcc66
6 75 98 ffcc66
7 75 98 ffcc66
8 75 98 ffcc66
9 75 98 ffcc66
10 75 98 ffcc66
11 75 98 ffcc66
12 75 98 ffcc66
13 75 98 ffcc66
14 75 98 ffcc66
0 76 98 ffcc66
1 76 98 ffcc66
2 76 98 ffcc66
3 76 98 ffcc66
4 76 98 ffcc66
5 76 98 ffcc66
6 76 98 ffcc66
7 76 98 ffcc66
8 76 98 ffcc66
9 76 98 ffcc66
10 76 98 ffcc66
11 76 98 ffcc66
12 76 98 ffcc66
13 76 98 ffcc66
14 76 98 ffcc66
15 76 98 ffcc66
0 77 98 ffcc66
1 77 98 ffcc66
2 77 98 ffcc66
3 77 98 ffcc66
4 77 98 ffcc66
5 77 98 ffcc66
6 77 98 ffcc66
7 77 98 ffcc66
8 77 98 ffcc66
9 77 98 ffcc66
10 77 98 ffcc66
11 77 98 ffcc66
12 77 98 ffcc66
13 77 98 ffcc66
14 77 98 ffcc66
15 77 98 ffcc66
0 78 98 ffcc66
1 78 98 ffcc66
2 78 98 ffcc66
3 78 98 ffcc66
4 78 98 ffcc66
5 78 98 ffcc66
6 78 98 ffcc66
7 78 98 ffcc66
8 78 98 ffcc66
9 78 98 ffcc66
10 78 98 ffcc66
11 78 98 ffcc66
12 78 98 ffcc66
13 78 98 ffcc66
14 78 98 ffcc66
15 78 98 ffcc66
0 79 98 ffcc66
1 79 98 ffcc66
2 79 98 ffcc66
3 79 98 ffcc66
4 79 98 ffcc66
5 79 98 ffcc66
6 79 98 ffcc66
7 79 98 ffcc66
8 79 98 ffcc66
9 79 98 ffcc66
10 79 98 ffcc66
11 79 98 ffcc66
12 79 98 ffcc66
13 79 98 ffcc66
14 79 98 ffcc66
15 79 98 ffcc66
6 70 99 ffcc66
7 70 99 ffcc66
8 70 99 ffcc66
9 70 99 ffcc66
10 70 99 ffcc66
11 70 99 ffcc66
12 70 99 ffcc66
4 71 99 ffcc66
5 71 99 ffcc66
6 71 99 ffcc66
7 71 99 ee0000
8 71 99 ee0000
9 71 99 ffcc66
10 71 99 ffcc66
11 71 99 ffcc66
12 71 99 ffcc66
13 71 99 ffcc66
14 71 99 ffcc66
4 72 99 ffcc66
5 72 99 ffcc66
6 72 99 ee0000
7 72 99 ee0000
8 72 99 ee0000
9 72 99 ee0000
10 72 99 ee0000
11 72 99 ffcc66
12 72 99 ffcc66
13 72 99 ffcc66
14 72 99 ffcc66
15 72 99 ffcc66
0 73 99 ffcc66
3 73 99 ffcc66
4 73 99 ffcc66
5 73 99 ee0000
6 73 99 ee0000
7 73 99 ee0000
8 73 99 ee0000
9 73 99 ee0000
10 73 99 ee0000
11 73 99 ee0000
12 73 99 ffcc66
13 73 99 ffcc66
14 73 99 ffcc66
15 73 99 ffcc66
0 74 99 ffcc66
2 74 99 ffcc66
3 74 99 ffcc66
4 74 99 ee0000
5 74 99 ee0000
6 74 99 ee0000
7 74 99 ee0000
8 74 99 ee0000
9 74 99 ee0000
10 74 99 ee0000
11 74 99 ee0000
12 74 99 ffcc66
13 74 99 ffcc66
14 74 99 ffcc66
15 74 99 ffcc66
0 75 99 ffcc66
1 75 99 ffcc66
2 75 99 ffcc66
3 75 99 ffcc66
4 75 99 ee0000
5 75 99 ee0000
6 75 99 ee0000
7 75 99 ee0000
8 75 99 ee0000
9 75 99 ee0000
10 75 99 ee0000
11 75 99 ee0000
12 75 99 ee0000
13 75 99 ffcc66
14 75 99 ffcc66
15 75 99 ffcc66
0 76 99 ffcc66
1 76 99 ffcc66
2 76 99 ffcc66
3 76 99 ee0000
4 76 99 ee0000
5 76 99 ee0000
6 76 99 ee0000
7 76 99 ee0000
8 76 99 bbbbbb
9 76 99 bbbbbb
10 76 99 bbbbbb
11 76 99 ee0000
12 76 99 ee0000
13 76 99 ee0000
14 76 99 ffcc66
15 76 99 ffcc66
0 77 99 ee0000
1 77 99 ffcc66
2 77 99 ffcc66
3 77 99 ee0000
4 77 99 ee0000
5 77 99 ee0000
6 77 99 ee0000
7 77 99 bbbbbb
8 77 99 bbbbbb
9 77 99 bbbbbb
10 77 99 bbbbbb
11 77 99 bbbbbb
12 77 99 ee0000
13 77 99 ee0000
14 77 99 ee0000
15 77 99 ffcc66
0 78 99 ee0000
1 78 99 ffcc66
2 78 99 ffcc66
3 78 99 ee0000
4 78 99 ee0000
5 78 99 ee0000
6 78 99 bbbbbb
7 78 99 bbbbbb
8 78 99 bbbbbb
9 78 99 bbbbbb
10 78 99 bbbbbb
11 78 99 bbbbbb
12 78 99 bbbbbb
13 78 99 ee0000
14 78 99 ee0000
15 78 99 ee0000
0 79 99 ee0000
1 79 99 ffcc66
2 79 99 ffcc66
3 79 99 ee0000
4 79 99 ee0000
5 79 99 ee0000
6 79 99 bbbbbb
7 79 99 bbbbbb
8 79 99 bbbbbb
9 79 99 bbbbbb
10 79 99 bbbbbb
11 79 99 bbbbbb
12 79 99 bbbbbb
13 79 99 ee0000
14 79 99 ee0000
15 79 99 ee0000
6 70 100 ffcc66
7 70 100 ffcc66
8 70 100 ffcc66
9 70 100 ffcc66
10 70 100 ffcc66
11 70 100 ffcc66
12 70 100 ffcc66
5 71 100 ffcc66
6 71 100 ffcc66
7 71 100 ee0000
8 71 100 ee0000
9 71 100 ee0000
10 71 100 ee0000
11 71 100 ffcc66
12 71 100 ffcc66
13 71 100 ffcc66
4 72 100 ffcc66
5 72 100 ffcc66
6 72 100 ee0000
7 72 100 ee0000
8 72 100 ee0000
9 72 100 ee0000
10 72 100 ee0000
11 72 100 ee0000
12 72 100 ee0000
13 72 100 ffcc66
14 72 100 ffcc66
0 73 100 ffcc66
3 73 100 ffcc66
4 73 100 ffcc66
5 73 100 ee0000
6 73 100 ee0000
7 73 100 ee0000
8 73 100 ee0000
9 73 100 ee0000
10 73 100 ee0000
11 73 100 ee0000
12 73 100 ee0000
13 73 100 ee0000
14 73 100 ffcc66
15 73 100 ffcc66
0 74 100 ffcc66
3 74 100 ffcc66
4 74 100 ee0000
5 74 100 ee0000
6 74 100 ee0000
7 74 100 ee0000
8 74 100 ee0000
9 74 100 ee0000
10 74 100 ee0000
11 74 100 ee0000
12 74 100 ee0000
13 74 100 ee0000
14 74 100 ee0000
15 74 100 ffcc66
0 75 100 ffcc66
2 75 100 ffcc66
3 75 100 ffcc66
4 75 100 ee0000
5 75 100 ee0000
6 75 100 ee0000
7 75 100 ee0000
8 75 100 ee0000
9 75 100 ee0000
10 75 100 ee0000
11 75 100 ee0000
12 75 100 ee0000
13 75 100 ee0000
14 75 100 ee0000
15 75 100 ffcc66
0 76 100 ffcc66
1 76 100 ffcc66
2 76 100 ffcc66
3 76 100 ee0000
4 76 100 ee0000
5 76 100 ee0000
6 76 100 ee0000
7 76 100 ee0000
8 76 100 bbbbbb
9 76 100 bbbbbb
10 76 100 bbbbbb
11 76 100 ee0000
12 76 100 ee0000
13 76 100 ee0000
14 76 100 ee0000
15 76 100 ee0000
0 77 100 ee0000
1 77 100 ffcc66
2 77 100 ffcc66
3 77 100 ee0000
4 77 100 ee0000
5 77 100 ee0000
6 77 100 ee0000
7 77 100 bbbbbb
8 77 100 bbbbbb
9 77 100 bbbbbb
10 77 100 bbbbbb
11 77 100 bbbbbb
12 77 100 ee0000
13 77 100 ee0000
14 77 100 ee0000
15 77 100 ee0000
0 78 100 ee0000
1 78 100 ffcc66
2 78 100 ffcc66
3 78 100 ee0000
4 78 100 ee0000
5 78 100 ee0000
6 78 100 bbbbbb
7 78 100 bbbbbb
8 78 100 bbbbbb
9 78 100 bbbbbb
10 78 100 bbbbbb
11 78 100 bbbbbb
12 78 100 bbbbbb
13 78 100 ee0000
14 78 100 ee0000
15 78 100 ee0000
0 79 100 ee0000
1 79 100 ffcc66
2 79 100 ffcc66
3 79 100 ee0000
4 79 100 ee0000
5 79 100 ee0000
6 79 100 bbbbbb
7 79 100 bbbbbb
8 79 100 bbbbbb
9 79 100 bbbbbb
10 79 100 bbbbbb
11 79 100 bbbbbb
12 79 100 bbbbbb
13 79 100 ee0000
14 79 100 ee0000
15 79 100 ee0000
6 70 101 ffcc66
7 70 101 ffcc66
8 70 101 ffcc66
9 70 101 ffcc66
10 70 101 ffcc66
11 70 101 ffcc66
5 71 101 ffcc66
6 71 101 ffcc66
7 71 101 ee0000
8 71 101 ee0000
9 71 101 ee0000
10 71 101 ffcc66
11 71 101 ffcc66
12 71 101 ffcc66
13 71 101 ffcc66
4 72 101 ffcc66
5 72 101 ffcc66
6 72 101 ee0000
7 72 101 ee0000
8 72 101 ee0000
9 72 101 ee0000
10 72 101 ee0000
11 72 101 ee0000
12 72 101 ffcc66
13 72 101 ffcc66
14 72 101 ffcc66
0 73 101 ffcc66
3 73 101 ffcc66
4 73 101 ffcc66
5 73 101 ee0000
6 73 101 ee0000
7 73 101 ee0000
8 73 101 ee0000
9 73 101 ee0000
10 73 101 ee0000
11 73 101 ee0000
12 73 101 ee0000
13 73 101 ffcc66
14 73 101 ffcc66
15 73 101 ffcc66
0 74 101 ffcc66
3 74 101 ffcc66
4 74 101 ee0000
5 74 101 ee0000
6 74 101 ee0000
7 74 101 ee0000
8 74 101 ee0000
9 74 101 ee0000
10 74 101 ee0000
11 74 101 ee0000
12 74 101 ee0000
13 74 101 ee0000
14 74 101 ffcc66
15 74 101 ffcc66
0 75 101 ffcc66
2 75 101 ffcc66
3 75 101 ffcc66
4 75 101 ee0000
5 75 101 ee0000
6 75 101 ee0000
7 75 101 ee0000
8 75 101 ee0000
9 75 101 ee0000
10 75 101 ee0000
11 75 101 ee0000
12 75 101 ee0000
13 75 101 ee0000
14 75 101 ee0000
15 75 101 ffcc66
0 76 101 ffcc66
1 76 101 ffcc66
2 76 101 ffcc66
3 76 101 ee0000
4 76 101 ee0000
5 76 101 ee0000
6 76 101 ee0000
7 76 101 ee0000
8 76 101 bbbbbb
9 76 101 bbbbbb
10 76 101 bbbbbb
11 76 101 ee0000
12 76 101 ee0000
13 76 101 ee0000
14 76 101 ee0000
15 76 101 ffcc66
0 77 101 ee0000
1 77 101 ffcc66
2 77 101 ffcc66
3 77 101 ee0000
4 77 101 ee0000
5 77 101 ee0000
6 77 101 ee0000
7 77 101 bbbbbb
8 77 101 bbbbbb
9 77 101 bbbbbb
10 77 101 bbbbbb
11 77 101 bbbbbb
12 77 101 ee0000
13 77 101 ee0000
14 77 101 ee0000
0 78 101 ee0000
1 78 101 ffcc66
2 78 101 ffcc66
3 78 101 ee0000
4 78 101 ee0000
5 78 101 ee0000
6 78 101 bbbbbb
7 78 101 bbbbbb
8 78 101 bbbbbb
9 78 101 bbbbbb
10 78 101 bbbbbb
11 78 101 bbbbbb
12 78 101 bbbbbb
13 78 101 ee0000
14 78 101 ee0000
0 79 101 ee0000
1 79 101 ffcc66
2 79 101 ffcc66
3 79 101 ee0000
4 79 101 ee0000
5 79 101 ee0000
6 79 101 bbbbbb
7 79 101 bbbbbb
8 79 101 bbbbbb
9 79 101 bbbbbb
10 79 101 bbbbbb
11 79 101 bbbbbb
12 79 101 bbbbbb
13 79 101 ee0000
14 79 101 ee0000
6 70 102 ffcc66
7 70 102 ffcc66
8 70 102 ffcc66
9 70 102 ffcc66
10 70 102 ffcc66
11 70 102 ffcc66
4 71 102 ffcc66
5 71 102 ffcc66
6 71 102 ffcc66
7 71 102 ee0000
8 71 102 ee0000
9 71 102 ee0000
10 71 102 ee0000
11 71 102 ffcc66
12 71 102 ffcc66
4 72 102 ffcc66
5 72 102 ffcc66
6 72 102 ee0000
7 72 102 ee0000
8 72 102 ee0000
9 72 102 ee0000
10 72 102 ee0000
11 72 102 ee0000
12 72 102 ffcc66
13 72 102 ffcc66
0 73 102 ffcc66
3 73 102 ffcc66
4 73 102 ffcc66
5 73 102 ee0000
6 73 102 ee0000
7 73 102 ee0000
8 73 102 ee0000
9 73 102 ee0000
10 73 102 ee0000
11 73 102 ee0000
12 73 102 ee0000
13 73 102 ffcc66
14 73 102 ffcc66
0 74 102 ffcc66
2 74 102 ffcc66
3 74 102 ffcc66
4 74 102 ee0000
5 74 102 ee0000
6 74 102 ee0000
7 74 102 ee0000
8 74 102 ee0000
9 74 102 ee0000
10 74 102 ee0000
11 74 102 ee0000
12 74 102 ee0000
13 74 102 ee0000
14 74 102 ffcc66
15 74 102 ffcc66
0 75 102 ffcc66
1 75 102 ffcc66
2 75 102 ffcc66
3 75 102 ffcc66
4 75 102 ee0000
5 75 102 ee0000
6 75 102 ee0000
7 75 102 ee0000
8 75 102 ee0000
9 75 102 ee0000
10 75 102 ee0000
11 75 102 ee0000
12 75 102 ee0000
13 75 102 ee0000
14 75 102 ee0000
15 75 102 ffcc66
0 76 102 ffcc66
1 76 102 ffcc66
2 76 102 ffcc66
3 76 102 ee0000
4 76 102 ee0000
5 76 102 ee0000
6 76 102 ee0000
7 76 102 ee0000
8 76 102 bbbbbb
9 76 102 bbbbbb
10 76 102 bbbbbb
11 76 102 ee0000
12 76 102 ee0000
13 76 102 ee0000
14 76 102 ee0000
15 76 102 ffcc66
0 77 102 ee0000
1 77 102 ffcc66
2 77 102 ffcc66
4 77 102 ee0000
5 77 102 ee0000
6 77 102 ee0000
7 77 102 bbbbbb
8 77 102 bbbbbb
9 77 102 bbbbbb
10 77 102 bbbbbb
11 77 102 bbbbbb
12 77 102 ee0000
13 77 102 ee0000
14 77 102 ee0000
15 77 102 ffcc66
0 78 102 ee0000
1 78 102 ffcc66
2 78 102 ffcc66
4 78 102 ee0000
5 78 102 ee0000
6 78 102 bbbbbb
7 78 102 bbbbbb
8 78 102 bbbbbb
9 78 102 bbbbbb
10 78 102 bbbbbb
11 78 102 bbbbbb
12 78 102 bbbbbb
13 78 102 ee0000
14 78 102 ee0000
0 79 102 ee0000
1 79 102 ee0000
2 79 102 ee0000
4 79 102 ee0000
5 79 102 ee0000
6 79 102 bbbbbb
7 79 102 bbbbbb
8 79 102 bbbbbb
9 79 102 bbbbbb
10 79 102 bbbbbb
11 79 102 bbbbbb
12 79 102 bbbbbb
13 79 102 ee0000
14 79 102 ee0000
6 69 103 ffcc66
7 69 103 ffcc66
8 69 103 ffcc66
9 69 103 ffcc66
10 69 103 ffcc66
5 70 103 ffcc66
6 70 103 ffcc66
7 70 103 ffcc66
8 70 103 ffcc66
9 70 103 ffcc66
10 70 103 ffcc66
11 70 103 ffcc66
4 71 103 ffcc66
5 71 103 ffcc66
6 71 103 ffcc66
7 71 103 ee0000
8 71 103 ee0000
9 71 103 ee0000
10 71 103 ee0000
11 71 103 ffcc66
12 71 103 ffcc66
0 72 103 ffcc66
3 72 103 ffcc66
4 72 103 ffcc66
5 72 103 ee0000
6 72 103 ee0000
7 72 103 ee0000
8 72 103 ee0000
9 72 103 ee0000
10 72 103 ee0000
11 72 103 ee0000
12 72 103 ffcc66
13 72 103 ffcc66
0 73 103 ffcc66
2 73 103 ffcc66
3 73 103 ffcc66
4 73 103 ffcc66
5 73 103 ee0000
6 73 103 ee0000
7 73 103 ee0000
8 73 103 ee0000
9 73 103 ee0000
10 73 103 ee0000
11 73 103 ee0000
12 73 103 ee0000
13 73 103 ffcc66
14 73 103 ffcc66
0 74 103 ffcc66
1 74 103 ffcc66
2 74 103 ffcc66
3 74 103 ffcc66
4 74 103 ee0000
5 74 103 ee0000
6 74 103 ee0000
7 74 103 ee0000
8 74 103 ee0000
9 74 103 ee0000
10 74 103 ee0000
11 74 103 ee0000
12 74 103 ee0000
13 74 103 ee0000
14 74 103 ffcc66
15 74 103 ffcc66
0 75 103 ffcc66
1 75 103 ffcc66
2 75 103 ffcc66
3 75 103 ee0000
4 75 103 ee0000
5 75 103 ee0000
6 75 103 ee0000
7 75 103 ee0000
8 75 103 ee0000
9 75 103 ee0000
10 75 103 ee0000
11 75 103 ee0000
12 75 103 ee0000
13 75 103 ee0000
14 75 103 ffcc66
15 75 103 ffcc66
0 76 103 ee0000
1 76 103 ffcc66
2 76 103 ffcc66
3 76 103 ee0000
4 76 103 ee0000
5 76 103 ee0000
6 76 103 ee0000
7 76 103 ee0000
8 76 103 bbbbbb
9 76 103 bbbbbb
10 76 103 bbbbbb
11 76 103 ee0000
12 76 103 ee0000
13 76 103 ee0000
14 76 103 ee0000
15 76 103 ffcc66
0 77 103 bbbbbb
1 77 103 bbbbbb
2 77 103 bbbbbb
3 77 103 bbbbbb
4 77 103 ee0000
5 77 103 ee0000
6 77 103 ee0000
7 77 103 bbbbbb
8 77 103 bbbbbb
9 77 103 bbbbbb
10 77 103 bbbbbb
11 77 103 bbbbbb
12 77 103 ee0000
13 77 103 ee0000
14 77 103 ee0000
15 77 103 ffcc66
0 78 103 bbbbbb
1 78 103 ee0000
2 78 103 bbbbbb
3 78 103 bbbbbb
4 78 103 ee0000
5 78 103 ee0000
6 78 103 bbbbbb
7 78 103 bbbbbb
8 78 103 bbbbbb
9 78 103 bbbbbb
10 78 103 bbbbbb
11 78 103 bbbbbb
12 78 103 bbbbbb
13 78 103 ee0000
14 78 103 ee0000
15 78 103 ffcc66
0 79 103 bbbbbb
1 79 103 ee0000
2 79 103 ee0000
3 79 103 bbbbbb
4 79 103 bbbbbb
5 79 103 ee0000
6 79 103 bbbbbb
7 79 103 bbbbbb
8 79 103 bbbbbb
9 79 103 bbbbbb
10 79 103 bbbbbb
11 79 103 bbbbbb
12 79 103 bbbbbb
13 79 103 ee0000
14 79 103 ee0000
5 69 104 ffcc66
6 69 104 ffcc66
7 69 104 ffcc66
8 69 104 ffcc66
9 69 104 ffcc66
10 69 104 ffcc66
4 70 104 ffcc66
5 70 104 ffcc66
6 70 104 ffcc66
7 70 104 ee0000
8 70 104 ee0000
9 70 104 ee0000
10 70 104 ffcc66
11 70 104 ffcc66
12 70 104 ffcc66
0 71 104 ffcc66
3 71 104 ffcc66
4 71 104 ffcc66
5 71 104 ffcc66
6 71 104 ee0000
7 71 104 ee0000
8 71 104 ee0000
9 71 104 ee0000
10 71 104 ee0000
11 71 104 ffcc66
12 71 104 ffcc66
0 72 104 ffcc66
2 72 104 ffcc66
3 72 104 ffcc66
4 72 104 ffcc66
5 72 104 ee0000
6 72 104 ee0000
7 72 104 ee0000
8 72 104 ee0000
9 72 104 ee0000
10 72 104 ee0000
11 72 104 ee0000
12 72 104 ffcc66
13 72 104 ffcc66
0 73 104 ffcc66
1 73 104 ffcc66
2 73 104 ffcc66
3 73 104 ffcc66
4 73 104 ee0000
5 73 104 ee0000
6 73 104 ee0000
7 73 104 ee0000
8 73 104 ee0000
9 73 104 ee0000
10 73 104 ee0000
11 73 104 ee0000
12 73 104 ee0000
13 73 104 ffcc66
14 73 104 ffcc66
0 74 104 ffcc66
1 74 104 ffcc66
2 74 104 ffcc66
3 74 104 ee0000
4 74 104 ee0000
5 74 104 ee0000
6 74 104 ee0000
7 74 104 ee0000
8 74 104 ee0000
9 74 104 ee0000
10 74 104 ee0000
11 74 104 ee0000
12 74 104 ee0000
13 74 104 ee0000
14 74 104 ffcc66
0 75 104 ee0000
1 75 104 bbbbbb
2 75 104 bbbbbb
3 75 104 ee0000
4 75 104 ee0000
5 75 104 ee0000
6 75 104 ee0000
7 75 104 ee0000
8 75 104 ee0000
9 75 104 ee0000
10 75 104 ee0000
11 75 104 ee0000
12 75 104 ee0000
13 75 104 ee0000
14 75 104 ffcc66
15 75 104 ffcc66
0 76 104 ee0000
1 76 104 bbbbbb
2 76 104 bbbbbb
3 76 104 ee0000
4 76 104 ee0000
5 76 104 ee0000
6 76 104 ee0000
7 76 104 ee0000
8 76 104 ee0000
9 76 104 ee0000
10 76 104 ee0000
11 76 104 ee0000
12 76 104 ee0000
13 76 104 ee0000
14 76 104 ee0000
15 76 104 ffcc66
0 77 104 ee0000
1 77 104 ee0000
2 77 104 ee0000
3 77 104 ee0000
4 77 104 ee0000
5 77 104 ee0000
6 77 104 ee0000
7 77 104 ee0000
8 77 104 bbbbbb
9 77 104 bbbbbb
10 77 104 bbbbbb
11 77 104 bbbbbb
12 77 104 ee0000
13 77 104 ee0000
14 77 104 ee0000
15 77 104 ffcc66
0 78 104 ee0000
1 78 104 ee0000
2 78 104 ee0000
3 78 104 ee0000
4 78 104 ee0000
5 78 104 ee0000
6 78 104 ee0000
7 78 104 bbbbbb
8 78 104 bbbbbb
9 78 104 bbbbbb
10 78 104 bbbbbb
11 78 104 bbbbbb
13 78 104 ee0000
14 78 104 ee0000
15 78 104 ffcc66
0 79 104 ee0000
1 79 104 ee0000
2 79 104 ee0000
3 79 104 ee0000
4 79 104 ee0000
5 79 104 ee0000
6 79 104 ee0000
7 79 104 bbbbbb
8 79 104 bbbbbb
9 79 104 bbbbbb
10 79 104 bbbbbb
11 79 104 bbbbbb
13 79 104 ee0000
14 79 104 ee0000
15 79 104 ffcc66
6 68 105 ffcc66
7 68 105 ffcc66
8 68 105 ffcc66
9 68 105 ffcc66
4 69 105 ffcc66
5 69 105 ffcc66
6 69 105 ffcc66
7 69 105 ffcc66
8 69 105 ffcc66
9 69 105 ffcc66
10 69 105 ffcc66
11 69 105 ffcc66
0 70 105 ffcc66
3 70 105 ffcc66
4 70 105 ffcc66
5 70 105 ffcc66
6 70 105 ee0000
7 70 105 ee0000
8 70 105 ee0000
9 70 105 ee0000
10 70 105 ffcc66
11 70 105 ffcc66
12 70 105 ffcc66
0 71 105 ffcc66
2 71 105 ffcc66
3 71 105 ffcc66
4 71 105 ffcc66
5 71 105 ee0000
6 71 105 ee0000
7 71 105 ee0000
8 71 105 ee0000
9 71 105 ee0000
10 71 105 ee0000
11 71 105 ee0000
12 71 105 ffcc66
13 71 105 ffcc66
0 72 105 ffcc66
1 72 105 ffcc66
2 72 105 ffcc66
3 72 105 ffcc66
4 72 105 ee0000
5 72 105 ee0000
6 72 105 ee0000
7 72 105 ee0000
8 72 105 ee0000
9 72 105 ee0000
10 72 105 ee0000
11 72 105 ee0000
12 72 105 ffcc66
13 72 105 ffcc66
0 73 105 ffcc66
1 73 105 ffcc66
2 73 105 ffcc66
3 73 105 ee0000
4 73 105 ee0000
5 73 105 ee0000
6 73 105 ee0000
7 73 105 ee0000
8 73 105 ee0000
9 73 105 ee0000
10 73 105 ee0000
11 73 105 ee0000
12 73 105 ee0000
13 73 105 ffcc66
14 73 105 ffcc66
0 74 105 ee0000
1 74 105 bbbbbb
2 74 105 bbbbbb
3 74 105 ee0000
4 74 105 ee0000
5 74 105 ee0000
6 74 105 ee0000
7 74 105 ee0000
8 74 105 ee0000
9 74 105 ee0000
10 74 105 ee0000
11 74 105 ee0000
12 74 105 ee0000
13 74 105 ee0000
14 74 105 ffcc66
0 75 105 ee0000
1 75 105 663300
2 75 105 663300
3 75 105 ee0000
4 75 105 ee0000
5 75 105 ee0000
6 75 105 ee0000
7 75 105 ee0000
8 75 105 ee0000
9 75 105 ee0000
10 75 105 ee0000
11 75 105 ee0000
12 75 105 ee0000
13 75 105 ee0000
14 75 105 ffcc66
15 75 105 ffcc66
0 76 105 ee0000
1 76 105 663300
2 76 105 663300
3 76 105 ee0000
4 76 105 ee0000
5 76 105 ee0000
6 76 105 ee0000
7 76 105 ee0000
8 76 105 ee0000
9 76 105 ee0000
10 76 105 ee0000
11 76 105 ee0000
12 76 105 ee0000
13 76 105 ee0000
14 76 105 ffcc66
15 76 105 ffcc66
0 77 105 ee0000
1 77 105 ee0000
2 77 105 ee0000
3 77 105 ee0000
4 77 105 ee0000
5 77 105 ee0000
6 77 105 ee0000
7 77 105 ee0000
8 77 105 ee0000
9 77 105 ee0000
10 77 105 ee0000
11 77 105 ee0000
12 77 105 ee0000
13 77 105 ee0000
14 77 105 ee0000
15 77 105 ffcc66
0 78 105 33ffff
1 78 105 33ffff
2 78 105 33ffff
3 78 105 33ffff
4 78 105 ee0000
5 78 105 ee0000
6 78 105 ee0000
7 78 105 ee0000
8 78 105 bbbbbb
9 78 105 bbbbbb
10 78 105 bbbbbb
11 78 105 ee0000
12 78 105 ee0000
13 78 105 ee0000
14 78 105 ee0000
15 78 105 ffcc66
0 79 105 33ffff
1 79 105 33ffff
2 79 105 33ffff
3 79 105 33ffff
4 79 105 33ffff
5 79 105 ee0000
6 79 105 ee0000
7 79 105 ee0000
8 79 105 bbbbbb
9 79 105 bbbbbb
10 79 105 bbbbbb
11 79 105 ee0000
12 79 105 ee0000
13 79 105 ee0000
14 79 105 ee0000
15 79 105 ffcc66
5 68 106 ffcc66
6 68 106 ffcc66
7 68 106 ffcc66
8 68 106 ffcc66
9 68 106 ffcc66
3 69 106 ffcc66
4 69 106 ffcc66
5 69 106 ffcc66
6 69 106 ffcc66
7 69 106 ee0000
8 69 106 ee0000
9 69 106 ffcc66
10 69 106 ffcc66
11 69 106 ffcc66
0 70 106 ffcc66
3 70 106 ffcc66
4 70 106 ffcc66
5 70 106 ee0000
6 70 106 ee0000
7 70 106 ee0000
8 70 106 ee0000
9 70 106 ee0000
10 70 106 ee0000
11 70 106 ffcc66
12 70 106 ffcc66
0 71 106 ffcc66
1 71 106 ffcc66
2 71 106 ffcc66
3 71 106 ffcc66
4 71 106 ee0000
5 71 106 ee0000
6 71 106 ee0000
7 71 106 ee0000
8 71 106 ee0000
9 71 106 ee0000
10 71 106 ee0000
11 71 106 ee0000
12 71 106 ffcc66
13 71 106 ffcc66
0 72 106 ffcc66
1 72 106 ffcc66
2 72 106 ffcc66
3 72 106 ee0000
4 72 106 ee0000
5 72 106 ee0000
6 72 106 ee0000
7 72 106 ee0000
8 72 106 ee0000
9 72 106 ee0000
10 72 106 ee0000
11 72 106 ee0000
12 72 106 ffcc66
13 72 106 ffcc66
0 73 106 ee0000
1 73 106 bbbbbb
2 73 106 bbbbbb
3 73 106 ee0000
4 73 106 ee0000
5 73 106 ee0000
6 73 106 ee0000
7 73 106 ee0000
8 73 106 ee0000
9 73 106 ee0000
10 73 106 ee0000
11 73 106 ee0000
12 73 106 ee0000
13 73 106 ffcc66
14 73 106 ffcc66
0 74 106 ee0000
1 74 106 bbbbbb
2 74 106 bbbbbb
3 74 106 ee0000
4 74 106 ee0000
5 74 106 ee0000
6 74 106 ee0000
7 74 106 ee0000
8 74 106 ee0000
9 74 106 ee0000
10 74 106 ee0000
11 74 106 ee0000
12 74 106 ee0000
13 74 106 ee0000
14 74 106 ffcc66
0 75 106 ee0000
1 75 106 663300
2 75 106 663300
3 75 106 ee0000
4 75 106 ee0000
5 75 106 ee0000
6 75 106 ee0000
7 75 106 ee0000
8 75 106 ee0000
9 75 106 ee0000
10 75 106 ee0000
11 75 106 ee0000
12 75 106 ee0000
13 75 106 ee0000
14 75 106 ffcc66
0 76 106 ee0000
1 76 106 663300
2 76 106 663300
3 76 106 ee0000
4 76 106 ee0000
5 76 106 ee0000
6 76 106 ee0000
7 76 106 ee0000
8 76 106 ee0000
9 76 106 ee0000
10 76 106 ee0000
11 76 106 ee0000
12 76 106 ee0000
13 76 106 ee0000
14 76 106 ffcc66
15 76 106 ffcc66
0 77 106 ee0000
1 77 106 33ffff
2 77 106 33ffff
3 77 106 ee0000
4 77 106 ee0000
5 77 106 ee0000
6 77 106 ee0000
7 77 106 ee0000
8 77 106 ee0000
9 77 106 ee0000
10 77 106 ee0000
11 77 106 ee0000
12 77 106 ee0000
13 77 106 ee0000
14 77 106 ee0000
15 77 106 ffcc66
0 78 106 33ffff
1 78 106 33ffff
2 78 106 33ffff
3 78 106 33ffff
4 78 106 ee0000
5 78 106 ee0000
6 78 106 ee0000
7 78 106 ee0000
8 78 106 ee0000
9 78 106 ee0000
10 78 106 bbbbbb
11 78 106 bbbbbb
12 78 106 ee0000
13 78 106 ee0000
14 78 106 ee0000
15 78 106 ffcc66
0 79 106 33ffff
1 79 106 33ffff
2 79 106 33ffff
3 79 106 33ffff
4 79 106 33ffff
5 79 106 ee0000
6 79 106 ee0000
7 79 106 ee0000
8 79 106 ee0000
9 79 106 bbbbbb
10 79 106 bbbbbb
11 79 106 bbbbbb
12 79 106 ee0000
13 79 106 ee0000
14 79 106 ee0000
15 79 106 ffcc66
4 68 107 ffcc66
5 68 107 ffcc66
6 68 107 ffcc66
7 68 107 ffcc66
8 68 107 ffcc66
9 68 107 ffcc66
0 69 107 ffcc66
3 69 107 ffcc66
4 69 107 ffcc66
5 69 107 ffcc66
6 69 107 ee0000
7 69 107 ee0000
8 69 107 ee0000
9 69 107 ffcc66
10 69 107 ffcc66
11 69 107 ffcc66
0 70 107 ffcc66
2 70 107 ffcc66
3 70 107 ffcc66
4 70 107 ee0000
5 70 107 ee0000
6 70 107 ee0000
7 70 107 ee0000
8 70 107 ee0000
9 70 107 ee0000
10 70 107 ee0000
11 70 107 ffcc66
12 70 107 ffcc66
0 71 107 ffcc66
1 71 107 ffcc66
2 71 107 ffcc66
3 71 107 ffcc66
4 71 107 ee0000
5 71 107 ee0000
6 71 107 ee0000
7 71 107 ee0000
8 71 107 ee0000
9 71 107 ee0000
10 71 107 ee0000
11 71 107 ee0000
12 71 107 ffcc66
0 72 107 ee0000
1 72 107 ffcc66
2 72 107 ffcc66
3 72 107 ee0000
4 72 107 ee0000
5 72 107 ee0000
6 72 107 ee0000
7 72 107 ee0000
8 72 107 ee0000
9 72 107 ee0000
10 72 107 ee0000
11 72 107 ee0000
12 72 107 ffcc66
13 72 107 ffcc66
0 73 107 ee0000
1 73 107 bbbbbb
2 73 107 bbbbbb
3 73 107 ee0000
4 73 107 ee0000
5 73 107 ee0000
6 73 107 ee0000
7 73 107 ee0000
8 73 107 ee0000
9 73 107 ee0000
10 73 107 ee0000
11 73 107 ee0000
12 73 107 ee0000
13 73 107 ffcc66
14 73 107 ffcc66
0 74 107 ee0000
1 74 107 ee0000
2 74 107 ee0000
3 74 107 ee0000
4 74 107 ee0000
5 74 107 ee0000
6 74 107 ee0000
7 74 107 ee0000
8 74 107 ee0000
9 74 107 ee0000
10 74 107 ee0000
11 74 107 ee0000
12 74 107 ee0000
13 74 107 ffcc66
14 74 107 ffcc66
0 75 107 ee0000
1 75 107 663300
2 75 107 663300
3 75 107 ee0000
4 75 107 ee0000
5 75 107 ee0000
6 75 107 cc0066
7 75 107 cc0066
8 75 107 cc0066
9 75 107 ee0000
10 75 107 ee0000
11 75 107 ee0000
12 75 107 bbbbbb
13 75 107 ee0000
14 75 107 ffcc66
0 76 107 ee0000
1 76 107 663300
2 76 107 663300
3 76 107 ee0000
4 76 107 ee0000
5 76 107 ee0000
6 76 107 cc0066
7 76 107 cc0066
8 76 107 cc0066
9 76 107 ee0000
10 76 107 ee0000
11 76 107 ee0000
12 76 107 bbbbbb
13 76 107 ee0000
14 76 107 ffcc66
15 76 107 ffcc66
0 77 107 ee0000
1 77 107 33ffff
2 77 107 33ffff
3 77 107 ee0000
4 77 107 ee0000
5 77 107 ee0000
6 77 107 cc0066
7 77 107 cc0066
8 77 107 ee0000
9 77 107 ee0000
10 77 107 ee0000
11 77 107 bbbbbb
12 77 107 bbbbbb
13 77 107 ee0000
14 77 107 ffcc66
15 77 107 ffcc66
0 78 107 33ffff
1 78 107 33ffff
2 78 107 33ffff
3 78 107 33ffff
4 78 107 ee0000
5 78 107 ee0000
6 78 107 cc0066
7 78 107 ee0000
8 78 107 ee0000
9 78 107 ee0000
10 78 107 ee0000
11 78 107 bbbbbb
12 78 107 bbbbbb
13 78 107 ee0000
14 78 107 ee0000
15 78 107 ffcc66
0 79 107 33ffff
1 79 107 33ffff
2 79 107 33ffff
3 79 107 33ffff
4 79 107 33ffff
5 79 107 cc0066
6 79 107 cc0066
7 79 107 ee0000
8 79 107 ee0000
9 79 107 ee0000
10 79 107 bbbbbb
11 79 107 bbbbbb
12 79 107 bbbbbb
13 79 107 ee0000
14 79 107 ee0000
15 79 107 ffcc66
4 68 108 ffcc66
5 68 108 ffcc66
6 68 108 ffcc66
7 68 108 ffcc66
8 68 108 ffcc66
9 68 108 ffcc66
0 69 108 ffcc66
3 69 108 ffcc66
4 69 108 ffcc66
5 69 108 ee0000
6 69 108 ee0000
7 69 108 ee0000
8 69 108 ee0000
9 69 108 ffcc66
10 69 108 ffcc66
11 69 108 ffcc66
0 70 108 ffcc66
1 70 108 ffcc66
2 70 108 ffcc66
3 70 108 ffcc66
4 70 108 ee0000
5 70 108 ee0000
6 70 108 ee0000
7 70 108 ee0000
8 70 108 ee0000
9 70 108 ee0000
10 70 108 ee0000
11 70 108 ffcc66
12 70 108 ffcc66
0 71 108 ffcc66
1 71 108 ffcc66
2 71 108 ffcc66
3 71 108 ee0000
4 71 108 ee0000
5 71 108 ee0000
6 71 108 ee0000
7 71 108 ee0000
8 71 108 ee0000
9 71 108 ee0000
10 71 108 ee0000
11 71 108 ee0000
12 71 108 ffcc66
0 72 108 ee0000
1 72 108 bbbbbb
2 72 108 bbbbbb
3 72 108 ee0000
4 72 108 ee0000
5 72 108 ee0000
6 72 108 ee0000
7 72 108 ee0000
8 72 108 ee0000
9 72 108 ee0000
10 72 108 ee0000
11 72 108 ee0000
12 72 108 ffcc66
13 72 108 ffcc66
0 73 108 ee0000
1 73 108 ee0000
2 73 108 ee0000
3 73 108 ee0000
4 73 108 ee0000
5 73 108 ee0000
6 73 108 ee0000
7 73 108 ee0000
8 73 108 ee0000
9 73 108 ee0000
10 73 108 ee0000
11 73 108 ee0000
12 73 108 ee0000
13 73 108 ffcc66
0 74 108 ee0000
1 74 108 ee0000
2 74 108 ee0000
3 74 108 ee0000
4 74 108 ee0000
5 74 108 ee0000
6 74 108 ee0000
7 74 108 ee0000
8 74 108 cc0066
9 74 108 cc0066
10 74 108 ee0000
11 74 108 ee0000
12 74 108 bbbbbb
13 74 108 ffcc66
14 74 108 ffcc66
0 75 108 ee0000
1 75 108 663300
2 75 108 663300
3 75 108 ee0000
4 75 108 ee0000
5 75 108 ee0000
6 75 108 ee0000
7 75 108 ee0000
8 75 108 cc0066
9 75 108 cc0066
10 75 108 ee0000
11 75 108 ee0000
12 75 108 bbbbbb
13 75 108 ee0000
14 75 108 ffcc66
0 76 108 ee0000
1 76 108 663300
2 76 108 663300
3 76 108 ee0000
4 76 108 ee0000
5 76 108 ee0000
6 76 108 ee0000
7 76 108 ee0000
8 76 108 ee0000
9 76 108 ee0000
10 76 108 ee0000
11 76 108 ee0000
12 76 108 bbbbbb
13 76 108 ee0000
14 76 108 ffcc66
0 77 108 ee0000
1 77 108 ee0000
2 77 108 ee0000
3 77 108 ee0000
4 77 108 ee0000
5 77 108 ee0000
6 77 108 ee0000
7 77 108 ee0000
8 77 108 ee0000
9 77 108 ee0000
10 77 108 ee0000
11 77 108 ee0000
12 77 108 bbbbbb
13 77 108 ee0000
14 77 108 ffcc66
15 77 108 ffcc66
0 78 108 33ffff
1 78 108 33ffff
2 78 108 33ffff
3 78 108 33ffff
4 78 108 ee0000
5 78 108 ee0000
6 78 108 ee0000
7 78 108 ee0000
8 78 108 ee0000
9 78 108 ee0000
10 78 108 ee0000
11 78 108 ee0000
12 78 108 bbbbbb
13 78 108 ee0000
14 78 108 ffcc66
15 78 108 ffcc66
0 79 108 33ffff
1 79 108 33ffff
2 79 108 33ffff
3 79 108 33ffff
4 79 108 33ffff
5 79 108 cc0066
6 79 108 ee0000
7 79 108 ee0000
8 79 108 ee0000
9 79 108 cc0066
10 79 108 ee0000
11 79 108 bbbbbb
12 79 108 bbbbbb
13 79 108 ee0000
14 79 108 ee0000
15 79 108 ffcc66
4 68 109 ffcc66
5 68 109 ffcc66
6 68 109 ffcc66
7 68 109 ffcc66
8 68 109 ffcc66
9 68 109 ffcc66
0 69 109 ffcc66
3 69 109 ffcc66
4 69 109 ffcc66
5 69 109 ee0000
6 69 109 ee0000
7 69 109 ee0000
8 69 109 ee0000
9 69 109 ffcc66
10 69 109 ffcc66
11 69 109 ffcc66
0 70 109 ffcc66
1 70 109 ffcc66
2 70 109 ffcc66
3 70 109 ffcc66
4 70 109 ee0000
5 70 109 ee0000
6 70 109 ee0000
7 70 109 ee0000
8 70 109 ee0000
9 70 109 ee0000
10 70 109 ee0000
11 70 109 ffcc66
12 70 109 ffcc66
0 71 109 ee0000
1 71 109 ffcc66
2 71 109 ffcc66
3 71 109 ee0000
4 71 109 ee0000
5 71 109 ee0000
6 71 109 ee0000
7 71 109 ee0000
8 71 109 ee0000
9 71 109 ee0000
10 71 109 ee0000
11 71 109 ffcc66
12 71 109 ffcc66
0 72 109 ee0000
1 72 109 bbbbbb
2 72 109 bbbbbb
3 72 109 ee0000
4 72 109 ee0000
5 72 109 ee0000
6 72 109 ee0000
7 72 109 ee0000
8 72 109 ee0000
9 72 109 ee0000
10 72 109 ee0000
11 72 109 ee0000
12 72 109 ffcc66
13 72 109 ffcc66
0 73 109 ee0000
1 73 109 ee0000
2 73 109 ee0000
3 73 109 ee0000
4 73 109 ee0000
5 73 109 ee0000
6 73 109 ee0000
7 73 109 ee0000
8 73 109 ee0000
9 73 109 ee0000
10 73 109 ee0000
11 73 109 ee0000
12 73 109 bbbbbb
13 73 109 ffcc66
0 74 109 ee0000
1 74 109 ee0000
2 74 109 ee0000
3 74 109 ee0000
4 74 109 ee0000
5 74 109 ee0000
6 74 109 ee0000
7 74 109 ee0000
8 74 109 ee0000
9 74 109 cc0066
10 74 109 ee0000
11 74 109 ee0000
12 74 109 bbbbbb
13 74 109 ffcc66
14 74 109 ffcc66
0 75 109 ee0000
1 75 109 663300
2 75 109 663300
3 75 109 ee0000
4 75 109 ee0000
5 75 109 ee0000
6 75 109 ee0000
7 75 109 ee0000
8 75 109 ee0000
9 75 109 cc0066
10 75 109 ee0000
11 75 109 ee0000
12 75 109 bbbbbb
13 75 109 ee0000
14 75 109 ffcc66
0 76 109 ee0000
1 76 109 663300
2 76 109 663300
3 76 109 ee0000
4 76 109 ee0000
5 76 109 0000ff
6 76 109 ee0000
7 76 109 ee0000
8 76 109 ee0000
9 76 109 ee0000
10 76 109 ee0000
11 76 109 ee0000
12 76 109 bbbbbb
13 76 109 ee0000
14 76 109 ffcc66
0 77 109 ee0000
1 77 109 ee0000
2 77 109 ee0000
3 77 109 ee0000
4 77 109 0000ff
5 77 109 0000ff
6 77 109 ee0000
7 77 109 ee0000
8 77 109 ee0000
9 77 109 ee0000
10 77 109 ee0000
11 77 109 ee0000
12 77 109 bbbbbb
13 77 109 ee0000
14 77 109 ffcc66
0 78 109 0000ff
1 78 109 ee0000
2 78 109 ee0000
3 78 109 ee0000
4 78 109 0000ff
5 78 109 ee0000
6 78 109 ee0000
7 78 109 ee0000
8 78 109 ee0000
9 78 109 ee0000
10 78 109 ee0000
11 78 109 ee0000
12 78 109 bbbbbb
13 78 109 ee0000
14 78 109 ffcc66
15 78 109 ffcc66
0 79 109 33ffff
1 79 109 33ffff
2 79 109 33ffff
3 79 109 33ffff
4 79 109 cc0066
5 79 109 cc0066
6 79 109 ee0000
7 79 109 ee0000
8 79 109 ee0000
9 79 109 cc0066
10 79 109 cc0066
11 79 109 ee0000
12 79 109 bbbbbb
13 79 109 ee0000
14 79 109 ee0000
15 79 109 ffcc66
4 68 110 ffcc66
5 68 110 ffcc66
6 68 110 ffcc66
7 68 110 ffcc66
8 68 110 ffcc66
9 68 110 ffcc66
0 69 110 ffcc66
3 69 110 ffcc66
4 69 110 ffcc66
5 69 110 ee0000
6 69 110 ee0000
7 69 110 ee0000
8 69 110 ee0000
9 69 110 ffcc66
10 69 110 ffcc66
11 69 110 ffcc66
0 70 110 ffcc66
1 70 110 ffcc66
2 70 110 ffcc66
3 70 110 ffcc66
4 70 110 ee0000
5 70 110 ee0000
6 70 110 ee0000
7 70 110 ee0000
8 70 110 ee0000
9 70 110 ee0000
10 70 110 ffcc66
11 70 110 ffcc66
0 71 110 ee0000
1 71 110 bbbbbb
2 71 110 bbbbbb
3 71 110 ee0000
4 71 110 ee0000
5 71 110 ee0000
6 71 110 ee0000
7 71 110 ee0000
8 71 110 ee0000
9 71 110 ee0000
10 71 110 ee0000
11 71 110 ffcc66
12 71 110 ffcc66
0 72 110 ee0000
1 72 110 bbbbbb
2 72 110 bbbbbb
3 72 110 ee0000
4 72 110 ee0000
5 72 110 ee0000
6 72 110 ee0000
7 72 110 ee0000
8 72 110 ee0000
9 72 110 ee0000
10 72 110 ee0000
11 72 110 ee0000
12 72 110 ffcc66
13 72 110 ffcc66
0 73 110 ee0000
1 73 110 ee0000
2 73 110 ee0000
3 73 110 ee0000
4 73 110 ee0000
5 73 110 ee0000
6 73 110 ee0000
7 73 110 ee0000
8 73 110 ee0000
9 73 110 ee0000
10 73 110 ee0000
11 73 110 ee0000
12 73 110 bbbbbb
13 73 110 ffcc66
0 74 110 ee0000
1 74 110 ee0000
2 74 110 ee0000
3 74 110 ee0000
4 74 110 ee0000
5 74 110 0000ff
6 74 110 ee0000
7 74 110 ee0000
8 74 110 ee0000
9 74 110 cc0066
10 74 110 ee0000
11 74 110 ee0000
12 74 110 bbbbbb
13 74 110 ffcc66
14 74 110 ffcc66
0 75 110 ff6633
1 75 110 ff6633
2 75 110 ff6633
3 75 110 ff6633
4 75 110 ee0000
5 75 110 0000ff
6 75 110 ee0000
7 75 110 ee0000
8 75 110 ee0000
9 75 110 cc0066
10 75 110 ee0000
11 75 110 ee0000
12 75 110 bbbbbb
13 75 110 ffcc66
14 75 110 ffcc66
0 76 110 ff6633
1 76 110 ff6633
2 76 110 ff6633
3 76 110 ff6633
4 76 110 ee0000
5 76 110 0000ff
6 76 110 ee0000
7 76 110 ee0000
8 76 110 ee0000
9 76 110 ee0000
10 76 110 ee0000
11 76 110 ee0000
12 76 110 bbbbbb
13 76 110 ee0000
14 76 110 ffcc66
0 77 110 ee0000
1 77 110 ff6633
2 77 110 ff6633
3 77 110 ee0000
4 77 110 ee0000
5 77 110 ee0000
6 77 110 ee0000
7 77 110 ee0000
8 77 110 ee0000
9 77 110 ee0000
10 77 110 ee0000
11 77 110 ee0000
12 77 110 bbbbbb
13 77 110 ee0000
14 77 110 ffcc66
0 78 110 ee0000
1 78 110 ee0000
2 78 110 ee0000
3 78 110 ee0000
4 78 110 ee0000
5 78 110 ee0000
6 78 110 ee0000
7 78 110 ee0000
8 78 110 ee0000
9 78 110 ee0000
10 78 110 ee0000
11 78 110 bbbbbb
12 78 110 bbbbbb
13 78 110 ee0000
14 78 110 ffcc66
15 78 110 ffcc66
0 79 110 cc0066
1 79 110 cc0066
2 79 110 ee0000
3 79 110 ee0000
4 79 110 ee0000
5 79 110 ee0000
6 79 110 ee0000
7 79 110 ee0000
8 79 110 ee0000
9 79 110 cc0066
10 79 110 ee0000
11 79 110 bbbbbb
12 79 110 bbbbbb
13 79 110 ee0000
14 79 110 ffcc66
15 79 110 ffcc66
4 68 111 ffcc66
5 68 111 ffcc66
6 68 111 ffcc66
7 68 111 ffcc66
8 68 111 ffcc66
9 68 111 ffcc66
0 69 111 ffcc66
3 69 111 ffcc66
4 69 111 ffcc66
5 69 111 bbbbbb
6 69 111 bbbbbb
7 69 111 bbbbbb
8 69 111 ffcc66
9 69 111 ffcc66
10 69 111 ffcc66
0 70 111 ffcc66
1 70 111 ffcc66
2 70 111 ffcc66
3 70 111 ffcc66
4 70 111 bbbbbb
5 70 111 bbbbbb
6 70 111 bbbbbb
7 70 111 bbbbbb
8 70 111 bbbbbb
9 70 111 bbbbbb
10 70 111 ffcc66
11 70 111 ffcc66
0 71 111 bbbbbb
1 71 111 bbbbbb
2 71 111 bbbbbb
3 71 111 bbbbbb
4 71 111 bbbbbb
5 71 111 bbbbbb
6 71 111 ee0000
7 71 111 ee0000
8 71 111 ee0000
9 71 111 bbbbbb
10 71 111 bbbbbb
11 71 111 ffcc66
12 71 111 ffcc66
0 72 111 bbbbbb
1 72 111 bbbbbb
2 72 111 bbbbbb
3 72 111 bbbbbb
4 72 111 bbbbbb
5 72 111 bbbbbb
6 72 111 ee0000
7 72 111 ee0000
8 72 111 ee0000
9 72 111 bbbbbb
10 72 111 bbbbbb
11 72 111 bbbbbb
12 72 111 ffcc66
13 72 111 ffcc66
0 73 111 ee0000
1 73 111 bbbbbb
2 73 111 bbbbbb
3 73 111 ee0000
4 73 111 ee0000
5 73 111 0000ff
6 73 111 ee0000
7 73 111 ee0000
8 73 111 ee0000
9 73 111 ee0000
10 73 111 bbbbbb
11 73 111 bbbbbb
12 73 111 bbbbbb
13 73 111 ffcc66
0 74 111 ee0000
1 74 111 ee0000
2 74 111 ee0000
3 74 111 ee0000
4 74 111 ee0000
5 74 111 0000ff
6 74 111 cc0066
7 74 111 ee0000
8 74 111 ee0000
9 74 111 cc0066
10 74 111 ee0000
11 74 111 bbbbbb
12 74 111 bbbbbb
13 74 111 ffcc66
0 75 111 ff6633
1 75 111 ff6633
2 75 111 ff6633
3 75 111 ff6633
4 75 111 ee0000
5 75 111 ee0000
6 75 111 ee0000
7 75 111 ee0000
8 75 111 ee0000
9 75 111 cc0066
10 75 111 ee0000
11 75 111 bbbbbb
12 75 111 bbbbbb
13 75 111 ffcc66
14 75 111 ffcc66
0 76 111 ff6633
1 76 111 ff6633
2 76 111 ff6633
3 76 111 ff6633
4 76 111 ee0000
5 76 111 ee0000
6 76 111 ee0000
7 76 111 ee0000
8 76 111 ee0000
9 76 111 ee0000
10 76 111 ee0000
11 76 111 bbbbbb
12 76 111 bbbbbb
13 76 111 ee0000
14 76 111 ffcc66
0 77 111 ee0000
1 77 111 ff6633
2 77 111 ff6633
3 77 111 ee0000
4 77 111 ee0000
5 77 111 ee0000
6 77 111 ee0000
7 77 111 ee0000
8 77 111 ee0000
9 77 111 ee0000
10 77 111 ee0000
11 77 111 bbbbbb
12 77 111 bbbbbb
13 77 111 ee0000
14 77 111 ffcc66
0 78 111 ee0000
1 78 111 ee0000
2 78 111 ee0000
3 78 111 ee0000
4 78 111 ee0000
5 78 111 ee0000
6 78 111 ee0000
7 78 111 ee0000
8 78 111 ee0000
9 78 111 ee0000
10 78 111 ee0000
11 78 111 bbbbbb
12 78 111 bbbbbb
13 78 111 ee0000
14 78 111 ffcc66
0 79 111 cc0066
1 79 111 cc0066
2 79 111 ee0000
3 79 111 ee0000
4 79 111 ee0000
5 79 111 ee0000
6 79 111 ee0000
7 79 111 ee0000
8 79 111 ee0000
9 79 111 cc0066
10 79 111 ee0000
11 79 111 bbbbbb
12 79 111 bbbbbb
13 79 111 ee0000
14 79 111 ffcc66
15 79 111 ffcc66
16 77 98 ffcc66
16 78 98 ffcc66
17 78 98 ffcc66
16 79 98 ffcc66
17 79 98 ffcc66
16 74 99 ffcc66
16 75 99 ffcc66
16 76 99 ffcc66
16 77 99 ffcc66
17 77 99 ffcc66
16 78 99 ffcc66
17 78 99 ffcc66
16 79 99 ee0000
17 79 99 ffcc66
16 75 100 ffcc66
16 76 100 ffcc66
16 77 100 ffcc66
16 78 100 ffcc66
17 78 100 ffcc66
16 79 100 ffcc66
17 79 100 ffcc66
16 75 101 ffcc66
16 76 101 ffcc66
16 77 101 ffcc66
16 78 101 ffcc66
16 79 101 ffcc66
16 76 102 ffcc66
16 77 102 ffcc66
16 78 102 ffcc66
16 79 102 ffcc66
16 77 103 ffcc66
16 78 103 ffcc66
16 79 103 ffcc66
16 78 104 ffcc66
16 79 104 ffcc66
16 79 105 ffcc66
-2 80 97 ffcc66
-1 80 97 ffcc66
-8 81 97 ffcc66
-7 81 97 ffcc66
-6 81 97 ffcc66
-5 81 97 ffcc66
-4 81 97 ffcc66
-3 81 97 ffcc66
-2 81 97 ffcc66
-1 81 97 ffcc66
-10 82 97 ffcc66
-9 82 97 ffcc66
-8 82 97 ffcc66
-7 82 97 ffcc66
-6 82 97 ffcc66
-5 82 97 ffcc66
-4 82 97 ffcc66
-3 82 97 ffcc66
-2 82 97 ffcc66
-1 82 97 ffcc66
-12 83 97 ffcc66
-11 83 97 ffcc66
-10 83 97 ffcc66
-9 83 97 ffcc66
-8 83 97 ffcc66
-7 83 97 ffcc66
-6 83 97 ffcc66
-5 83 97 ffcc66
-4 83 97 ffcc66
-3 83 97 ffcc66
-2 83 97 ffcc66
-1 83 97 ffcc66
-13 84 97 ffcc66
-12 84 97 ffcc66
-11 84 97 ffcc66
-10 84 97 ffcc66
-9 84 97 ffcc66
-8 84 97 ffcc66
-7 84 97 ffcc66
-6 84 97 ffcc66
-5 84 97 ffcc66
-4 84 97 ffcc66
-3 84 97 ffcc66
-2 84 97 ffcc66
-1 84 97 ffcc66
-13 85 97 ffcc66
-12 85 97 ffcc66
-11 85 97 ffcc66
-10 85 97 ffcc66
-9 85 97 ffcc66
-8 85 97 ffcc66
-7 85 97 ffcc66
-6 85 97 ffcc66
-5 85 97 ffcc66
-4 85 97 ffcc66
-3 85 97 ffcc66
-2 85 97 ffcc66
-1 85 97 ffcc66
-13 86 97 ffcc66
-12 86 97 ffcc66
-11 86 97 ffcc66
-10 86 97 ffcc66
-9 86 97 ffcc66
-8 86 97 ffcc66
-7 86 97 ffcc66
-6 86 97 ffcc66
-5 86 97 ffcc66
-4 86 97 ffcc66
-3 86 97 ffcc66
-2 86 97 ffcc66
-11 87 97 ffcc66
-10 87 97 ffcc66
-9 87 97 ffcc66
-8 87 97 ffcc66
-7 87 97 ffcc66
-6 87 97 ffcc66
-5 87 97 ffcc66
-4 87 97 ffcc66
-10 88 97 ffcc66
-9 88 97 ffcc66
-8 88 97 ffcc66
-7 88 97 ffcc66
-6 88 97 ffcc66
-14 80 98 ffcc66
-13 80 98 ffcc66
-12 80 98 ffcc66
-11 80 98 ffcc66
-10 80 98 ffcc66
-9 80 98 ffcc66
-8 80 98 ffcc66
-7 80 98 ffcc66
-6 80 98 ffcc66
-5 80 98 ffcc66
-4 80 98 ffcc66
-3 80 98 ffcc66
-2 80 98 ffcc66
-1 80 98 ffcc66
-14 81 98 ffcc66
-13 81 98 ffcc66
-12 81 98 ffcc66
-11 81 98 ffcc66
-10 81 98 ffcc66
-9 81 98 ffcc66
-8 81 98 ffcc66
-7 81 98 ffcc66
-6 81 98 ffcc66
-5 81 98 ffcc66
-4 81 98 ffcc66
-3 81 98 ffcc66
-2 81 98 ffcc66
-1 81 98 ee0000
-14 82 98 ffcc66
-13 82 98 ffcc66
-12 82 98 ffcc66
-11 82 98 ffcc66
-10 82 98 ffcc66
-9 82 98 ffcc66
-8 82 98 ffcc66
-7 82 98 bbbbbb
-6 82 98 bbbbbb
-5 82 98 bbbbbb
-4 82 98 bbbbbb
-3 82 98 ee0000
-2 82 98 ee0000
-1 82 98 ee0000
-14 83 98 ffcc66
-13 83 98 ffcc66
-12 83 98 ffcc66
-11 83 98 ffcc66
-10 83 98 ffcc66
-9 83 98 ee0000
-8 83 98 ee0000
-7 83 98 bbbbbb
-6 83 98 bbbbbb
-5 83 98 bbbbbb
-4 83 98 ee0000
-3 83 98 ee0000
-2 83 98 ee0000
-1 83 98 ffcc66
-14 84 98 ffcc66
-13 84 98 ffcc66
-12 84 98 ffcc66
-11 84 98 ee0000
-10 84 98 ee0000
-9 84 98 ee0000
-8 84 98 ee0000
-7 84 98 ee0000
-6 84 98 ee0000
-5 84 98 ee0000
-4 84 98 ee0000
-3 84 98 ee0000
-2 84 98 ee0000
-1 84 98 ffcc66
-13 85 98 ffcc66
-12 85 98 ffcc66
-11 85 98 ee0000
-10 85 98 ee0000
-9 85 98 ee0000
-8 85 98 ee0000
-7 85 98 ee0000
-6 85 98 ee0000
-5 85 98 ee0000
-4 85 98 ee0000
-3 85 98 ee0000
-2 85 98 ffcc66
-1 85 98 ffcc66
-13 86 98 ffcc66
-12 86 98 ffcc66
-11 86 98 ffcc66
-10 86 98 ee0000
-9 86 98 ee0000
-8 86 98 ee0000
-7 86 98 ee0000
-6 86 98 ee0000
-5 86 98 ee0000
-4 86 98 ffcc66
-3 86 98 ffcc66
-2 86 98 ffcc66
-11 87 98 ffcc66
-10 87 98 ffcc66
-9 87 98 ee0000
-8 87 98 ee0000
-7 87 98 ee0000
-6 87 98 ffcc66
-5 87 98 ffcc66
-4 87 98 ffcc66
-3 87 98 ffcc66
-10 88 98 ffcc66
-9 88 98 ffcc66
-8 88 98 ffcc66
-7 88 98 ffcc66
-6 88 98 ffcc66
-14 80 99 ffcc66
-13 80 99 ee0000
-12 80 99 ee0000
-11 80 99 ee0000
-10 80 99 ee0000
-9 80 99 bbbbbb
-8 80 99 bbbbbb
-7 80 99 bbbbbb
-6 80 99 bbbbbb
-5 80 99 bbbbbb
-4 80 99 bbbbbb
-3 80 99 bbbbbb
-2 80 99 ee0000
-1 80 99 ee0000
-14 81 99 ffcc66
-13 81 99 ee0000
-12 81 99 ee0000
-11 81 99 ee0000
-10 81 99 ee0000
-9 81 99 bbbbbb
-8 81 99 bbbbbb
-7 81 99 bbbbbb
-6 81 99 bbbbbb
-5 81 99 bbbbbb
-4 81 99 bbbbbb
-3 81 99 bbbbbb
-2 81 99 ee0000
-1 81 99 ee0000
-14 82 99 ffcc66
-13 82 99 ee0000
-12 82 99 ee0000
-11 82 99 ee0000
-10 82 99 ee0000
-9 82 99 ee0000
-8 82 99 bbbbbb
-7 82 99 bbbbbb
-6 82 99 bbbbbb
-5 82 99 bbbbbb
-4 82 99 bbbbbb
-3 82 99 ee0000
-2 82 99 ee0000
-1 82 99 ee0000
-14 83 99 ffcc66
-13 83 99 ffcc66
-12 83 99 ee0000
-11 83 99 ee0000
-10 83 99 ee0000
-9 83 99 ee0000
-8 83 99 ee0000
-7 83 99 bbbbbb
-6 83 99 bbbbbb
-5 83 99 bbbbbb
-4 83 99 ee0000
-3 83 99 ee0000
-2 83 99 ee0000
-1 83 99 ee0000
-14 84 99 ffcc66
-13 84 99 ffcc66
-12 84 99 ee0000
-11 84 99 ee0000
-10 84 99 ee0000
-9 84 99 ee0000
-8 84 99 ee0000
-7 84 99 ee0000
-6 84 99 ee0000
-5 84 99 ee0000
-4 84 99 ee0000
-3 84 99 ee0000
-2 84 99 ee0000
-1 84 99 ffcc66
-13 85 99 ffcc66
-12 85 99 ffcc66
-11 85 99 ee0000
-10 85 99 ee0000
-9 85 99 ee0000
-8 85 99 ee0000
-7 85 99 ee0000
-6 85 99 ee0000
-5 85 99 ee0000
-4 85 99 ee0000
-3 85 99 ee0000
-2 85 99 ffcc66
-1 85 99 ffcc66
-12 86 99 ffcc66
-11 86 99 ffcc66
-10 86 99 ee0000
-9 86 99 ee0000
-8 86 99 ee0000
-7 86 99 ee0000
-6 86 99 ee0000
-5 86 99 ee0000
-4 86 99 ee0000
-3 86 99 ffcc66
-2 86 99 ffcc66
-1 86 99 ffcc66
-12 87 99 ffcc66
-11 87 99 ffcc66
-10 87 99 ffcc66
-9 87 99 ee0000
-8 87 99 ee0000
-7 87 99 ee0000
-6 87 99 ffcc66
-5 87 99 ffcc66
-4 87 99 ffcc66
-3 87 99 ffcc66
-10 88 99 ffcc66
-9 88 99 ffcc66
-8 88 99 ffcc66
-7 88 99 ffcc66
-6 88 99 ffcc66
-14 80 100 ffcc66
-13 80 100 ee0000
-12 80 100 ee0000
-11 80 100 ee0000
-10 80 100 ee0000
-9 80 100 bbbbbb
-8 80 100 bbbbbb
-7 80 100 bbbbbb
-6 80 100 bbbbbb
-5 80 100 bbbbbb
-4 80 100 bbbbbb
-3 80 100 bbbbbb
-2 80 100 ee0000
-1 80 100 ee0000
-14 81 100 ffcc66
-13 81 100 ee0000
-12 81 100 ee0000
-11 81 100 ee0000
-10 81 100 ee0000
-9 81 100 bbbbbb
-8 81 100 bbbbbb
-7 81 100 bbbbbb
-6 81 100 bbbbbb
-5 81 100 bbbbbb
-4 81 100 bbbbbb
-3 81 100 bbbbbb
-2 81 100 ee0000
-1 81 100 ee0000
-14 82 100 ffcc66
-13 82 100 ee0000
-12 82 100 ee0000
-11 82 100 ee0000
-10 82 100 ee0000
-9 82 100 ee0000
-8 82 100 bbbbbb
-7 82 100 bbbbbb
-6 82 100 bbbbbb
-5 82 100 bbbbbb
-4 82 100 bbbbbb
-3 82 100 ee0000
-2 82 100 ee0000
-1 82 100 ee0000
-14 83 100 ffcc66
-13 83 100 ffcc66
-12 83 100 ee0000
-11 83 100 ee0000
-10 83 100 ee0000
-9 83 100 ee0000
-8 83 100 ee0000
-7 83 100 bbbbbb
-6 83 100 bbbbbb
-5 83 100 bbbbbb
-4 83 100 ee0000
-3 83 100 ee0000
-2 83 100 ee0000
-1 83 100 ee0000
-13 84 100 ffcc66
-12 84 100 ee0000
-11 84 100 ee0000
-10 84 100 ee0000
-9 84 100 ee0000
-8 84 100 ee0000
-7 84 100 ee0000
-6 84 100 ee0000
-5 84 100 ee0000
-4 84 100 ee0000
-3 84 100 ee0000
-2 84 100 ee0000
-1 84 100 ee0000
-13 85 100 ffcc66
-12 85 100 ffcc66
-11 85 100 ee0000
-10 85 100 ee0000
-9 85 100 ee0000
-8 85 100 ee0000
-7 85 100 ee0000
-6 85 100 ee0000
-5 85 100 ee0000
-4 85 100 ee0000
-3 85 100 ee0000
-2 85 100 ee0000
-1 85 100 ffcc66
-12 86 100 ffcc66
-11 86 100 ffcc66
-10 86 100 ee0000
-9 86 100 ee0000
-8 86 100 ee0000
-7 86 100 ee0000
-6 86 100 ee0000
-5 86 100 ee0000
-4 86 100 ee0000
-3 86 100 ffcc66
-2 86 100 ffcc66
-1 86 100 ffcc66
-11 87 100 ffcc66
-10 87 100 ffcc66
-9 87 100 ee0000
-8 87 100 ee0000
-7 87 100 ee0000
-6 87 100 ffcc66
-5 87 100 ffcc66
-4 87 100 ffcc66
-3 87 100 ffcc66
-2 87 100 ffcc66
-10 88 100 ffcc66
-9 88 100 ffcc66
-8 88 100 ffcc66
-7 88 100 ffcc66
-6 88 100 ffcc66
-14 80 101 ffcc66
-13 80 101 ee0000
-12 80 101 ee0000
-11 80 101 ee0000
-10 80 101 ee0000
-9 80 101 bbbbbb
-8 80 101 bbbbbb
-7 80 101 bbbbbb
-6 80 101 bbbbbb
-5 80 101 bbbbbb
-4 80 101 bbbbbb
-3 80 101 bbbbbb
-2 80 101 ee0000
-1 80 101 ee0000
-14 81 101 ffcc66
-13 81 101 ee0000
-12 81 101 ee0000
-11 81 101 ee0000
-10 81 101 ee0000
-9 81 101 bbbbbb
-8 81 101 bbbbbb
-7 81 101 bbbbbb
-6 81 101 bbbbbb
-5 81 101 bbbbbb
-4 81 101 bbbbbb
-3 81 101 bbbbbb
-2 81 101 ee0000
-1 81 101 ee0000
-14 82 101 ffcc66
-13 82 101 ffcc66
-12 82 101 ee0000
-11 82 101 ee0000
-10 82 101 ee0000
-9 82 101 ee0000
-8 82 101 bbbbbb
-7 82 101 bbbbbb
-6 82 101 bbbbbb
-5 82 101 bbbbbb
-4 82 101 bbbbbb
-3 82 101 ee0000
-2 82 101 ee0000
-1 82 101 ee0000
-14 83 101 ffcc66
-13 83 101 ffcc66
-12 83 101 ee0000
-11 83 101 ee0000
-10 83 101 ee0000
-9 83 101 ee0000
-8 83 101 ee0000
-7 83 101 bbbbbb
-6 83 101 bbbbbb
-5 83 101 bbbbbb
-4 83 101 ee0000
-3 83 101 ee0000
-2 83 101 ee0000
-1 83 101 ee0000
-13 84 101 ffcc66
-12 84 101 ee0000
-11 84 101 ee0000
-10 84 101 ee0000
-9 84 101 ee0000
-8 84 101 ee0000
-7 84 101 ee0000
-6 84 101 ee0000
-5 84 101 ee0000
-4 84 101 ee0000
-3 84 101 ee0000
-2 84 101 ee0000
-1 84 101 ee0000
-13 85 101 ffcc66
-12 85 101 ffcc66
-11 85 101 ee0000
-10 85 101 ee0000
-9 85 101 ee0000
-8 85 101 ee0000
-7 85 101 ee0000
-6 85 101 ee0000
-5 85 101 ee0000
-4 85 101 ee0000
-3 85 101 ee0000
-2 85 101 ee0000
-1 85 101 ee0000
-12 86 101 ffcc66
-11 86 101 ffcc66
-10 86 101 ee0000
-9 86 101 ee0000
-8 86 101 ee0000
-7 86 101 ee0000
-6 86 101 ee0000
-5 86 101 ee0000
-4 86 101 ee0000
-3 86 101 ee0000
-2 86 101 ffcc66
-1 86 101 ffcc66
-11 87 101 ffcc66
-10 87 101 ffcc66
-9 87 101 ee0000
-8 87 101 ee0000
-7 87 101 ee0000
-6 87 101 ffcc66
-5 87 101 ffcc66
-4 87 101 ffcc66
-3 87 101 ffcc66
-2 87 101 ffcc66
-1 87 101 ffcc66
-10 88 101 ffcc66
-9 88 101 ffcc66
-8 88 101 ffcc66
-7 88 101 ffcc66
-6 88 101 ffcc66
-5 88 101 ffcc66
-14 80 102 ffcc66
-13 80 102 ffcc66
-12 80 102 ee0000
-11 80 102 ee0000
-10 80 102 ee0000
-9 80 102 bbbbbb
-8 80 102 bbbbbb
-7 80 102 bbbbbb
-6 80 102 bbbbbb
-5 80 102 bbbbbb
-4 80 102 bbbbbb
-3 80 102 bbbbbb
-2 80 102 ee0000
-1 80 102 ee0000
-14 81 102 ffcc66
-13 81 102 ffcc66
-12 81 102 ee0000
-11 81 102 ee0000
-10 81 102 ee0000
-9 81 102 bbbbbb
-8 81 102 bbbbbb
-7 81 102 bbbbbb
-6 81 102 bbbbbb
-5 81 102 bbbbbb
-4 81 102 bbbbbb
-3 81 102 bbbbbb
-2 81 102 ee0000
-1 81 102 ee0000
-14 82 102 ffcc66
-13 82 102 ffcc66
-12 82 102 ee0000
-11 82 102 ee0000
-10 82 102 ee0000
-9 82 102 ee0000
-8 82 102 bbbbbb
-7 82 102 bbbbbb
-6 82 102 bbbbbb
-5 82 102 bbbbbb
-4 82 102 bbbbbb
-3 82 102 ee0000
-2 82 102 ee0000
-1 82 102 ee0000
-13 83 102 ffcc66
-12 83 102 ee0000
-11 83 102 ee0000
-10 83 102 ee0000
-9 83 102 ee0000
-8 83 102 ee0000
-7 83 102 bbbbbb
-6 83 102 bbbbbb
-5 83 102 bbbbbb
-4 83 102 ee0000
-3 83 102 ee0000
-2 83 102 ee0000
-1 83 102 ee0000
-13 84 102 ffcc66
-12 84 102 ee0000
-11 84 102 ee0000
-10 84 102 ee0000
-9 84 102 ee0000
-8 84 102 ee0000
-7 84 102 ee0000
-6 84 102 ee0000
-5 84 102 ee0000
-4 84 102 ee0000
-3 84 102 ee0000
-2 84 102 ee0000
-1 84 102 ee0000
-13 85 102 ffcc66
-12 85 102 ffcc66
-11 85 102 ee0000
-10 85 102 ee0000
-9 85 102 ee0000
-8 85 102 ee0000
-7 85 102 ee0000
-6 85 102 ee0000
-5 85 102 ee0000
-4 85 102 ee0000
-3 85 102 ee0000
-2 85 102 ee0000
-1 85 102 ee0000
-12 86 102 ffcc66
-11 86 102 ffcc66
-10 86 102 ee0000
-9 86 102 ee0000
-8 86 102 ee0000
-7 86 102 ee0000
-6 86 102 ee0000
-5 86 102 ee0000
-4 86 102 ee0000
-3 86 102 ee0000
-2 86 102 ee0000
-1 86 102 ee0000
-11 87 102 ffcc66
-10 87 102 ffcc66
-9 87 102 ee0000
-8 87 102 ee0000
-7 87 102 ee0000
-6 87 102 ee0000
-5 87 102 ffcc66
-4 87 102 ffcc66
-3 87 102 ffcc66
-2 87 102 ffcc66
-1 87 102 ffcc66
-10 88 102 ffcc66
-9 88 102 ffcc66
-8 88 102 ffcc66
-7 88 102 ffcc66
-6 88 102 ffcc66
-5 88 102 ffcc66
-4 88 102 ffcc66
-2 88 102 ffcc66
-1 88 102 ffcc66
-13 80 103 ffcc66
-12 80 103 ee0000
-11 80 103 ee0000
-10 80 103 ee0000
-9 80 103 ee0000
-8 80 103 bbbbbb
-7 80 103 bbbbbb
-6 80 103 bbbbbb
-5 80 103 bbbbbb
-4 80 103 bbbbbb
-3 80 103 ee0000
-2 80 103 ee0000
-1 80 103 bbbbbb
-13 81 103 ffcc66
-12 81 103 ee0000
-11 81 103 ee0000
-10 81 103 ee0000
-9 81 103 ee0000
-8 81 103 bbbbbb
-7 81 103 bbbbbb
-6 81 103 bbbbbb
-5 81 103 bbbbbb
-4 81 103 bbbbbb
-3 81 103 ee0000
-2 81 103 ee0000
-1 81 103 bbbbbb
-13 82 103 ffcc66
-12 82 103 ee0000
-11 82 103 ee0000
-10 82 103 ee0000
-9 82 103 ee0000
-8 82 103 ee0000
-7 82 103 bbbbbb
-6 82 103 bbbbbb
-5 82 103 bbbbbb
-4 82 103 ee0000
-3 82 103 ee0000
-2 82 103 ee0000
-1 82 103 bbbbbb
-13 83 103 ffcc66
-12 83 103 ee0000
-11 83 103 ee0000
-10 83 103 ee0000
-9 83 103 ee0000
-8 83 103 ee0000
-7 83 103 ee0000
-6 83 103 ee0000
-5 83 103 ee0000
-4 83 103 ee0000
-3 83 103 ee0000
-2 83 103 ee0000
-1 83 103 bbbbbb
-13 84 103 ffcc66
-12 84 103 ee0000
-11 84 103 ee0000
-10 84 103 ee0000
-9 84 103 ee0000
-8 84 103 ee0000
-7 84 103 ee0000
-6 84 103 ee0000
-5 84 103 ee0000
-4 84 103 ee0000
-3 84 103 ee0000
-2 84 103 bbbbbb
-1 84 103 bbbbbb
-13 85 103 ffcc66
-12 85 103 ffcc66
-11 85 103 ee0000
-10 85 103 ee0000
-9 85 103 ee0000
-8 85 103 ee0000
-7 85 103 ee0000
-6 85 103 ee0000
-5 85 103 ee0000
-4 85 103 ee0000
-3 85 103 ee0000
-2 85 103 ee0000
-1 85 103 bbbbbb
-12 86 103 ffcc66
-11 86 103 ffcc66
-10 86 103 ee0000
-9 86 103 ee0000
-8 86 103 ee0000
-7 86 103 ee0000
-6 86 103 ee0000
-5 86 103 ee0000
-4 86 103 ee0000
-3 86 103 ee0000
-2 86 103 ee0000
-1 86 103 ee0000
-11 87 103 ffcc66
-10 87 103 ffcc66
-9 87 103 ee0000
-8 87 103 ee0000
-7 87 103 ee0000
-6 87 103 ee0000
-5 87 103 ee0000
-4 87 103 ffcc66
-3 87 103 ffcc66
-2 87 103 ffcc66
-1 87 103 bbbbbb
-10 88 103 ffcc66
-9 88 103 ffcc66
-8 88 103 ffcc66
-7 88 103 ffcc66
-6 88 103 ffcc66
-5 88 103 ffcc66
-4 88 103 ffcc66
-3 88 103 ffcc66
-2 88 103 ffcc66
-1 88 103 ffcc66
-13 80 104 ffcc66
-12 80 104 ee0000
-11 80 104 ee0000
-10 80 104 ee0000
-9 80 104 ee0000
-8 80 104 ee0000
-7 80 104 bbbbbb
-6 80 104 bbbbbb
-5 80 104 bbbbbb
-4 80 104 ee0000
-3 80 104 ee0000
-2 80 104 ee0000
-1 80 104 ee0000
-13 81 104 ffcc66
-12 81 104 ee0000
-11 81 104 ee0000
-10 81 104 ee0000
-9 81 104 ee0000
-8 81 104 ee0000
-7 81 104 bbbbbb
-6 81 104 bbbbbb
-5 81 104 bbbbbb
-4 81 104 ee0000
-3 81 104 ee0000
-2 81 104 ee0000
-1 81 104 ee0000
-13 82 104 ffcc66
-12 82 104 ee0000
-11 82 104 ee0000
-10 82 104 ee0000
-9 82 104 ee0000
-8 82 104 ee0000
-7 82 104 ee0000
-6 82 104 ee0000
-5 82 104 ee0000
-4 82 104 ee0000
-3 82 104 ee0000
-2 82 104 ee0000
-1 82 104 ee0000
-13 83 104 ffcc66
-12 83 104 ee0000
-11 83 104 ee0000
-10 83 104 ee0000
-9 83 104 ee0000
-8 83 104 ee0000
-7 83 104 ee0000
-6 83 104 ee0000
-5 83 104 ee0000
-4 83 104 ee0000
-3 83 104 ee0000
-2 83 104 ee0000
-1 83 104 ee0000
-13 84 104 ffcc66
-12 84 104 ffcc66
-11 84 104 ee0000
-10 84 104 ee0000
-9 84 104 ee0000
-8 84 104 ee0000
-7 84 104 ee0000
-6 84 104 ee0000
-5 84 104 ee0000
-4 84 104 ee0000
-3 84 104 ee0000
-2 84 104 ee0000
-1 84 104 ee0000
-13 85 104 ffcc66
-12 85 104 ffcc66
-11 85 104 ee0000
-10 85 104 ee0000
-9 85 104 ee0000
-8 85 104 ee0000
-7 85 104 ee0000
-6 85 104 ee0000
-5 85 104 ee0000
-4 85 104 ee0000
-3 85 104 ee0000
-2 85 104 ee0000
-1 85 104 ee0000
-12 86 104 ffcc66
-11 86 104 ffcc66
-10 86 104 ee0000
-9 86 104 ee0000
-8 86 104 ee0000
-7 86 104 ee0000
-6 86 104 ee0000
-5 86 104 ee0000
-4 86 104 ee0000
-3 86 104 ee0000
-2 86 104 ee0000
-1 86 104 ee0000
-11 87 104 ffcc66
-10 87 104 ffcc66
-9 87 104 ee0000
-8 87 104 ee0000
-7 87 104 ee0000
-6 87 104 ee0000
-5 87 104 ee0000
-4 87 104 bbbbbb
-3 87 104 bbbbbb
-2 87 104 bbbbbb
-1 87 104 bbbbbb
-10 88 104 ffcc66
-9 88 104 ffcc66
-8 88 104 ffcc66
-7 88 104 ffcc66
-6 88 104 ffcc66
-5 88 104 ffcc66
-4 88 104 ffcc66
-3 88 104 ffcc66
-2 88 104 ffcc66
-1 88 104 ffcc66
-1 89 104 ffcc66
-13 80 105 ffcc66
-12 80 105 ee0000
-11 80 105 ee0000
-10 80 105 ee0000
-9 80 105 ee0000
-8 80 105 bbbbbb
-7 80 105 bbbbbb
-6 80 105 ee0000
-5 80 105 ee0000
-4 80 105 ee0000
-3 80 105 ee0000
-2 80 105 ee0000
-1 80 105 33ffff
-13 81 105 ffcc66
-12 81 105 ee0000
-11 81 105 ee0000
-10 81 105 ee0000
-9 81 105 ee0000
-8 81 105 bbbbbb
-7 81 105 bbbbbb
-6 81 105 ee0000
-5 81 105 ee0000
-4 81 105 ee0000
-3 81 105 ee0000
-2 81 105 ee0000
-1 81 105 33ffff
-13 82 105 ffcc66
-12 82 105 ee0000
-11 82 105 ee0000
-10 82 105 ee0000
-9 82 105 ee0000
-8 82 105 ee0000
-7 82 105 ee0000
-6 82 105 ee0000
-5 82 105 ee0000
-4 82 105 ee0000
-3 82 105 ee0000
-2 82 105 ee0000
-1 82 105 33ffff
-13 83 105 ffcc66
-12 83 105 ffcc66
-11 83 105 ee0000
-10 83 105 ee0000
-9 83 105 ee0000
-8 83 105 ee0000
-7 83 105 ee0000
-6 83 105 ee0000
-5 83 105 ee0000
-4 83 105 ee0000
-3 83 105 ee0000
-2 83 105 ee0000
-1 83 105 ee0000
-13 84 105 ffcc66
-12 84 105 ffcc66
-11 84 105 ee0000
-10 84 105 ee0000
-9 84 105 ee0000
-8 84 105 ee0000
-7 84 105 ee0000
-6 84 105 ee0000
-5 84 105 ee0000
-4 84 105 ee0000
-3 84 105 ee0000
-2 84 105 ee0000
-1 84 105 ee0000
-12 85 105 ffcc66
-11 85 105 ee0000
-10 85 105 ee0000
-9 85 105 ee0000
-8 85 105 ee0000
-7 85 105 ee0000
-6 85 105 ee0000
-5 85 105 ee0000
-4 85 105 ee0000
-3 85 105 ee0000
-2 85 105 ee0000
-1 85 105 ee0000
-12 86 105 ffcc66
-11 86 105 ffcc66
-10 86 105 ee0000
-9 86 105 ee0000
-8 86 105 ee0000
-7 86 105 ee0000
-6 86 105 ee0000
-5 86 105 ee0000
-4 86 105 ee0000
-3 86 105 ee0000
-2 86 105 ee0000
-1 86 105 ee0000
-11 87 105 ffcc66
-10 87 105 ffcc66
-9 87 105 ffcc66
-8 87 105 ee0000
-7 87 105 ee0000
-6 87 105 ee0000
-5 87 105 bbbbbb
-4 87 105 bbbbbb
-3 87 105 bbbbbb
-2 87 105 ee0000
-1 87 105 ee0000
-10 88 105 ffcc66
-9 88 105 ffcc66
-8 88 105 ffcc66
-7 88 105 ffcc66
-6 88 105 ffcc66
-5 88 105 ffcc66
-4 88 105 ffcc66
-3 88 105 ffcc66
-2 88 105 ffcc66
-1 88 105 ffcc66
-2 89 105 ffcc66
-1 89 105 ffcc66
-13 80 106 ffcc66
-12 80 106 ffcc66
-11 80 106 ee0000
-10 80 106 bbbbbb
-9 80 106 bbbbbb
-8 80 106 bbbbbb
-7 80 106 ee0000
-6 80 106 ee0000
-5 80 106 ee0000
-4 80 106 ee0000
-3 80 106 ee0000
-2 80 106 33ffff
-1 80 106 33ffff
-13 81 106 ffcc66
-12 81 106 bbbbbb
-11 81 106 bbbbbb
-10 81 106 bbbbbb
-9 81 106 bbbbbb
-8 81 106 bbbbbb
-7 81 106 ee0000
-6 81 106 ee0000
-5 81 106 ee0000
-4 81 106 ee0000
-3 81 106 ee0000
-2 81 106 33ffff
-1 81 106 33ffff
-13 82 106 ffcc66
-12 82 106 bbbbbb
-11 82 106 bbbbbb
-10 82 106 bbbbbb
-9 82 106 ee0000
-8 82 106 ee0000
-7 82 106 ee0000
-6 82 106 ee0000
-5 82 106 ee0000
-4 82 106 ee0000
-3 82 106 ee0000
-2 82 106 ee0000
-1 82 106 33ffff
-13 83 106 ffcc66
-12 83 106 ffcc66
-11 83 106 ee0000
-10 83 106 ee0000
-9 83 106 ee0000
-8 83 106 ee0000
-7 83 106 ee0000
-6 83 106 ee0000
-5 83 106 ee0000
-4 83 106 ee0000
-3 83 106 ee0000
-2 83 106 ee0000
-1 83 106 ee0000
-12 84 106 ffcc66
-11 84 106 ee0000
-10 84 106 ee0000
-9 84 106 ee0000
-8 84 106 ee0000
-7 84 106 ee0000
-6 84 106 ee0000
-5 84 106 ee0000
-4 84 106 ee0000
-3 84 106 ee0000
-2 84 106 ee0000
-1 84 106 ee0000
-12 85 106 ffcc66
-11 85 106 ffcc66
-10 85 106 ee0000
-9 85 106 ee0000
-8 85 106 ee0000
-7 85 106 ee0000
-6 85 106 ee0000
-5 85 106 ee0000
-4 85 106 ee0000
-3 85 106 ee0000
-2 85 106 ee0000
-1 85 106 ee0000
-12 86 106 ffcc66
-11 86 106 ffcc66
-10 86 106 ee0000
-9 86 106 ee0000
-8 86 106 ee0000
-7 86 106 ee0000
-6 86 106 ee0000
-5 86 106 ee0000
-4 86 106 ee0000
-3 86 106 ee0000
-2 86 106 ee0000
-1 86 106 ee0000
-11 87 106 ffcc66
-10 87 106 ffcc66
-9 87 106 ffcc66
-8 87 106 ee0000
-7 87 106 ee0000
-6 87 106 bbbbbb
-5 87 106 bbbbbb
-4 87 106 bbbbbb
-3 87 106 ee0000
-2 87 106 ee0000
-1 87 106 ee0000
-9 88 106 ffcc66
-8 88 106 ffcc66
-7 88 106 ffcc66
-6 88 106 ffcc66
-5 88 106 ffcc66
-4 88 106 ffcc66
-3 88 106 ffcc66
-2 88 106 ffcc66
-1 88 106 ee0000
-3 89 106 ffcc66
-2 89 106 ffcc66
-1 89 106 ffcc66
-13 80 107 ffcc66
-12 80 107 ffcc66
-11 80 107 bbbbbb
-10 80 107 bbbbbb
-9 80 107 bbbbbb
-8 80 107 ee0000
-7 80 107 ee0000
-6 80 107 ff6633
-5 80 107 ff6633
-4 80 107 ee0000
-3 80 107 ee0000
-2 80 107 33ffff
-1 80 107 33ffff
-13 81 107 ffcc66
-12 81 107 ffcc66
-11 81 107 bbbbbb
-10 81 107 bbbbbb
-9 81 107 bbbbbb
-8 81 107 ee0000
-7 81 107 ee0000
-6 81 107 ff6633
-5 81 107 ff6633
-4 81 107 ee0000
-3 81 107 ee0000
-2 81 107 33ffff
-1 81 107 33ffff
-13 82 107 ffcc66
-12 82 107 ffcc66
-11 82 107 bbbbbb
-10 82 107 bbbbbb
-9 82 107 bbbbbb
-8 82 107 ee0000
-7 82 107 ee0000
-6 82 107 ff6633
-5 82 107 ff6633
-4 82 107 ee0000
-3 82 107 ee0000
-2 82 107 ee0000
-1 82 107 33ffff
-13 83 107 ffcc66
-12 83 107 ffcc66
-11 83 107 bbbbbb
-10 83 107 bbbbbb
-9 83 107 ee0000
-8 83 107 ee0000
-7 83 107 ee0000
-6 83 107 ff6633
-5 83 107 ff6633
-4 83 107 ee0000
-3 83 107 ee0000
-2 83 107 ee0000
-1 83 107 ee0000
-12 84 107 ffcc66
-11 84 107 ee0000
-10 84 107 ee0000
-9 84 107 ee0000
-8 84 107 ee0000
-7 84 107 ee0000
-6 84 107 ff6633
-5 84 107 ff6633
-4 84 107 ee0000
-3 84 107 ee0000
-2 84 107 ee0000
-1 84 107 ee0000
-12 85 107 ffcc66
-11 85 107 ffcc66
-10 85 107 ee0000
-9 85 107 ee0000
-8 85 107 ee0000
-7 85 107 ee0000
-6 85 107 ee0000
-5 85 107 ee0000
-4 85 107 ee0000
-3 85 107 ee0000
-2 85 107 ee0000
-1 85 107 ee0000
-11 86 107 ffcc66
-10 86 107 ffcc66
-9 86 107 ee0000
-8 86 107 ee0000
-7 86 107 ee0000
-6 86 107 ee0000
-5 86 107 ee0000
-4 86 107 ee0000
-3 86 107 ee0000
-2 86 107 ee0000
-1 86 107 ee0000
-11 87 107 ffcc66
-10 87 107 ffcc66
-9 87 107 ffcc66
-8 87 107 ffcc66
-7 87 107 bbbbbb
-6 87 107 bbbbbb
-5 87 107 bbbbbb
-4 87 107 ee0000
-3 87 107 ee0000
-2 87 107 ee0000
-1 87 107 ee0000
-9 88 107 ffcc66
-8 88 107 ffcc66
-7 88 107 ffcc66
-6 88 107 ffcc66
-5 88 107 ffcc66
-4 88 107 ffcc66
-3 88 107 ffcc66
-2 88 107 ee0000
-1 88 107 ee0000
-4 89 107 ffcc66
-3 89 107 ffcc66
-2 89 107 ffcc66
-1 89 107 ffcc66
-12 80 108 ffcc66
-11 80 108 bbbbbb
-10 80 108 bbbbbb
-9 80 108 ee0000
-8 80 108 cc0066
-7 80 108 cc0066
-6 80 108 ff6633
-5 80 108 ff6633
-4 80 108 ee0000
-3 80 108 ee0000
-2 80 108 ee0000
-1 80 108 33ffff
-12 81 108 ffcc66
-11 81 108 bbbbbb
-10 81 108 bbbbbb
-9 81 108 ee0000
-8 81 108 cc0066
-7 81 108 cc0066
-6 81 108 ff6633
-5 81 108 ff6633
-4 81 108 ee0000
-3 81 108 ee0000
-2 81 108 ee0000
-1 81 108 33ffff
-12 82 108 ffcc66
-11 82 108 bbbbbb
-10 82 108 bbbbbb
-9 82 108 ee0000
-8 82 108 cc0066
-7 82 108 cc0066
-6 82 108 ff6633
-5 82 108 ff6633
-4 82 108 ee0000
-3 82 108 ee0000
-2 82 108 ee0000
-1 82 108 33ffff
-12 83 108 ffcc66
-11 83 108 bbbbbb
-10 83 108 ee0000
-9 83 108 ee0000
-8 83 108 cc0066
-7 83 108 cc0066
-6 83 108 ff6633
-5 83 108 ff6633
-4 83 108 ff6633
-3 83 108 ee0000
-2 83 108 ee0000
-1 83 108 ee0000
-12 84 108 ffcc66
-11 84 108 ee0000
-10 84 108 ee0000
-9 84 108 ee0000
-8 84 108 ee0000
-7 84 108 cc0066
-6 84 108 ff6633
-5 84 108 ff6633
-4 84 108 ff6633
-3 84 108 ee0000
-2 84 108 ee0000
-1 84 108 ee0000
-12 85 108 ffcc66
-11 85 108 ffcc66
-10 85 108 ee0000
-9 85 108 ee0000
-8 85 108 ee0000
-7 85 108 cc0066
-6 85 108 cc0066
-5 85 108 cc0066
-4 85 108 ee0000
-3 85 108 ee0000
-2 85 108 ee0000
-1 85 108 ee0000
-11 86 108 ffcc66
-10 86 108 ffcc66
-9 86 108 ee0000
-8 86 108 ee0000
-7 86 108 ee0000
-6 86 108 ee0000
-5 86 108 ee0000
-4 86 108 ee0000
-3 86 108 ee0000
-2 86 108 ee0000
-1 86 108 ee0000
-10 87 108 ffcc66
-9 87 108 ffcc66
-8 87 108 ffcc66
-7 87 108 bbbbbb
-6 87 108 bbbbbb
-5 87 108 ee0000
-4 87 108 ee0000
-3 87 108 ee0000
-2 87 108 ee0000
-1 87 108 ee0000
-8 88 108 ffcc66
-7 88 108 ffcc66
-6 88 108 ffcc66
-5 88 108 ffcc66
-4 88 108 ffcc66
-3 88 108 ee0000
-2 88 108 ee0000
-1 88 108 ee0000
-4 89 108 ffcc66
-3 89 108 ffcc66
-2 89 108 ffcc66
-1 89 108 ffcc66
-12 80 109 ffcc66
-11 80 109 bbbbbb
-10 80 109 bbbbbb
-9 80 109 ee0000
-8 80 109 ee0000
-7 80 109 ee0000
-6 80 109 ee0000
-5 80 109 cc0066
-4 80 109 cc0066
-3 80 109 ee0000
-2 80 109 ee0000
-1 80 109 ee0000
-12 81 109 ffcc66
-11 81 109 bbbbbb
-10 81 109 bbbbbb
-9 81 109 ee0000
-8 81 109 ee0000
-7 81 109 ee0000
-6 81 109 ee0000
-5 81 109 cc0066
-4 81 109 cc0066
-3 81 109 cc0066
-2 81 109 cc0066
-1 81 109 ee0000
-12 82 109 ffcc66
-11 82 109 bbbbbb
-10 82 109 bbbbbb
-9 82 109 ee0000
-8 82 109 ee0000
-7 82 109 ee0000
-6 82 109 ee0000
-5 82 109 cc0066
-4 82 109 cc0066
-3 82 109 cc0066
-2 82 109 cc0066
-1 82 109 ee0000
-12 83 109 ffcc66
-11 83 109 bbbbbb
-10 83 109 bbbbbb
-9 83 109 ee0000
-8 83 109 ee0000
-7 83 109 ee0000
-6 83 109 ee0000
-5 83 109 ff6633
-4 83 109 ff6633
-3 83 109 ff6633
-2 83 109 cc0066
-1 83 109 cc0066
-12 84 109 ffcc66
-11 84 109 ffcc66
-10 84 109 ee0000
-9 84 109 ee0000
-8 84 109 cc0066
-7 84 109 cc0066
-6 84 109 cc0066
-5 84 109 ff6633
-4 84 109 ff6633
-3 84 109 ff6633
-2 84 109 cc0066
-1 84 109 cc0066
-12 85 109 ffcc66
-11 85 109 ffcc66
-10 85 109 ee0000
-9 85 109 ee0000
-8 85 109 ee0000
-7 85 109 ee0000
-6 85 109 cc0066
-5 85 109 cc0066
-4 85 109 cc0066
-3 85 109 cc0066
-2 85 109 cc0066
-1 85 109 ee0000
-11 86 109 ffcc66
-10 86 109 ffcc66
-9 86 109 ee0000
-8 86 109 ee0000
-7 86 109 bbbbbb
-6 86 109 ee0000
-5 86 109 cc0066
-4 86 109 cc0066
-3 86 109 cc0066
-2 86 109 cc0066
-1 86 109 ee0000
-10 87 109 ffcc66
-9 87 109 ffcc66
-8 87 109 ffcc66
-7 87 109 bbbbbb
-6 87 109 ee0000
-5 87 109 ee0000
-4 87 109 ee0000
-3 87 109 ee0000
-2 87 109 ee0000
-1 87 109 ee0000
-8 88 109 ffcc66
-7 88 109 ffcc66
-6 88 109 ffcc66
-5 88 109 ffcc66
-4 88 109 ffcc66
-3 88 109 ee0000
-2 88 109 ee0000
-1 88 109 ee0000
-5 89 109 ffcc66
-4 89 109 ffcc66
-3 89 109 ffcc66
-2 89 109 ffcc66
-1 89 109 ffcc66
-12 80 110 ffcc66
-11 80 110 bbbbbb
-10 80 110 bbbbbb
-9 80 110 ee0000
-8 80 110 ee0000
-7 80 110 ee0000
-6 80 110 ee0000
-5 80 110 ee0000
-4 80 110 ee0000
-3 80 110 ee0000
-2 80 110 ee0000
-1 80 110 ee0000
-12 81 110 ffcc66
-11 81 110 bbbbbb
-10 81 110 bbbbbb
-9 81 110 ee0000
-8 81 110 ee0000
-7 81 110 ee0000
-6 81 110 ee0000
-5 81 110 ee0000
-4 81 110 ee0000
-3 81 110 ee0000
-2 81 110 ee0000
-1 81 110 ee0000
-12 82 110 ffcc66
-11 82 110 bbbbbb
-10 82 110 bbbbbb
-9 82 110 ee0000
-8 82 110 ee0000
-7 82 110 ee0000
-6 82 110 ee0000
-5 82 110 ee0000
-4 82 110 ee0000
-3 82 110 ee0000
-2 82 110 ee0000
-1 82 110 ee0000
-12 83 110 ffcc66
-11 83 110 bbbbbb
-10 83 110 bbbbbb
-9 83 110 ee0000
-8 83 110 ee0000
-7 83 110 ee0000
-6 83 110 ee0000
-5 83 110 ee0000
-4 83 110 ff6633
-3 83 110 ff6633
-2 83 110 ff6633
-1 83 110 ee0000
-12 84 110 ffcc66
-11 84 110 ffcc66
-10 84 110 ee0000
-9 84 110 ee0000
-8 84 110 ee0000
-7 84 110 ee0000
-6 84 110 ee0000
-5 84 110 ee0000
-4 84 110 ff6633
-3 84 110 ff6633
-2 84 110 ff6633
-1 84 110 ee0000
-11 85 110 ffcc66
-10 85 110 ee0000
-9 85 110 ee0000
-8 85 110 ee0000
-7 85 110 ee0000
-6 85 110 ee0000
-5 85 110 ee0000
-4 85 110 ee0000
-3 85 110 ee0000
-2 85 110 ee0000
-1 85 110 ee0000
-11 86 110 ffcc66
-10 86 110 ffcc66
-9 86 110 ee0000
-8 86 110 ee0000
-7 86 110 bbbbbb
-6 86 110 ee0000
-5 86 110 ee0000
-4 86 110 ee0000
-3 86 110 ee0000
-2 86 110 ee0000
-1 86 110 ee0000
-10 87 110 ffcc66
-9 87 110 ffcc66
-8 87 110 ffcc66
-7 87 110 bbbbbb
-6 87 110 ee0000
-5 87 110 ee0000
-4 87 110 ee0000
-3 87 110 ee0000
-2 87 110 ee0000
-1 87 110 ee0000
-8 88 110 ffcc66
-7 88 110 ffcc66
-6 88 110 ffcc66
-5 88 110 ffcc66
-4 88 110 ee0000
-3 88 110 ee0000
-2 88 110 ee0000
-1 88 110 ee0000
-5 89 110 ffcc66
-4 89 110 ffcc66
-3 89 110 ffcc66
-2 89 110 ffcc66
-1 89 110 ffcc66
-12 80 111 ffcc66
-11 80 111 bbbbbb
-10 80 111 bbbbbb
-9 80 111 ee0000
-8 80 111 ee0000
-7 80 111 ee0000
-6 80 111 ee0000
-5 80 111 ee0000
-4 80 111 ee0000
-3 80 111 ee0000
-2 80 111 ee0000
-1 80 111 ee0000
-12 81 111 ffcc66
-11 81 111 bbbbbb
-10 81 111 bbbbbb
-9 81 111 ee0000
-8 81 111 ee0000
-7 81 111 ee0000
-6 81 111 ee0000
-5 81 111 ee0000
-4 81 111 ee0000
-3 81 111 ee0000
-2 81 111 ee0000
-1 81 111 ee0000
-12 82 111 ffcc66
-11 82 111 bbbbbb
-10 82 111 bbbbbb
-9 82 111 ee0000
-8 82 111 ee0000
-7 82 111 ee0000
-6 82 111 ee0000
-5 82 111 ee0000
-4 82 111 ee0000
-3 82 111 ee0000
-2 82 111 ee0000
-1 82 111 ee0000
-12 83 111 ffcc66
-11 83 111 bbbbbb
-10 83 111 bbbbbb
-9 83 111 ee0000
-8 83 111 ee0000
-7 83 111 ee0000
-6 83 111 ee0000
-5 83 111 ee0000
-4 83 111 ee0000
-3 83 111 ff6633
-2 83 111 ff6633
-1 83 111 ee0000
-12 84 111 ffcc66
-11 84 111 ffcc66
-10 84 111 bbbbbb
-9 84 111 bbbbbb
-8 84 111 ee0000
-7 84 111 ee0000
-6 84 111 ee0000
-5 84 111 ee0000
-4 84 111 ee0000
-3 84 111 ff6633
-2 84 111 ff6633
-1 84 111 ee0000
-11 85 111 ffcc66
-10 85 111 ffcc66
-9 85 111 bbbbbb
-8 85 111 bbbbbb
-7 85 111 ee0000
-6 85 111 ee0000
-5 85 111 ee0000
-4 85 111 ee0000
-3 85 111 ee0000
-2 85 111 ee0000
-1 85 111 ee0000
-11 86 111 ffcc66
-10 86 111 ffcc66
-9 86 111 ffcc66
-8 86 111 bbbbbb
-7 86 111 bbbbbb
-6 86 111 ee0000
-5 86 111 ee0000
-4 86 111 ee0000
-3 86 111 ee0000
-2 86 111 ee0000
-1 86 111 ee0000
-10 87 111 ffcc66
-9 87 111 ffcc66
-8 87 111 ffcc66
-7 87 111 bbbbbb
-6 87 111 ee0000
-5 87 111 ee0000
-4 87 111 ee0000
-3 87 111 ee0000
-2 87 111 ee0000
-1 87 111 ee0000
-8 88 111 ffcc66
-7 88 111 ffcc66
-6 88 111 ffcc66
-5 88 111 ffcc66
-4 88 111 ee0000
-3 88 111 ee0000
-2 88 111 ee0000
-1 88 111 ee0000
-5 89 111 ffcc66
-4 89 111 ffcc66
-3 89 111 ffcc66
-2 89 111 ffcc66
-1 89 111 ffcc66
0 80 97 ffcc66
1 80 97 ffcc66
2 80 97 ffcc66
3 80 97 ffcc66
4 80 97 ffcc66
0 81 97 ffcc66
1 81 97 ffcc66
2 81 97 ffcc66
3 81 97 ffcc66
4 81 97 ffcc66
5 81 97 ffcc66
6 81 97 ffcc66
7 81 97 ffcc66
8 81 97 ffcc66
9 81 97 ffcc66
10 81 97 ffcc66
11 81 97 ffcc66
0 82 97 ffcc66
2 82 97 ffcc66
3 82 97 ffcc66
4 82 97 ffcc66
5 82 97 ffcc66
6 82 97 ffcc66
7 82 97 ffcc66
8 82 97 ffcc66
9 82 97 ffcc66
10 82 97 ffcc66
11 82 97 ffcc66
12 82 97 ffcc66
13 82 97 ffcc66
0 83 97 ffcc66
3 83 97 ffcc66
4 83 97 ffcc66
5 83 97 ffcc66
6 83 97 ffcc66
7 83 97 ffcc66
8 83 97 ffcc66
9 83 97 ffcc66
10 83 97 ffcc66
11 83 97 ffcc66
12 83 97 ffcc66
13 83 97 ffcc66
14 83 97 ffcc66
15 83 97 ffcc66
3 84 97 ffcc66
4 84 97 ffcc66
5 84 97 ffcc66
6 84 97 ffcc66
7 84 97 ffcc66
8 84 97 ffcc66
9 84 97 ffcc66
10 84 97 ffcc66
11 84 97 ffcc66
12 84 97 ffcc66
13 84 97 ffcc66
14 84 97 ffcc66
15 84 97 ffcc66
4 85 97 ffcc66
5 85 97 ffcc66
6 85 97 ffcc66
7 85 97 ffcc66
8 85 97 ffcc66
9 85 97 ffcc66
10 85 97 ffcc66
11 85 97 ffcc66
12 85 97 ffcc66
13 85 97 ffcc66
14 85 97 ffcc66
15 85 97 ffcc66
5 86 97 ffcc66
6 86 97 ffcc66
7 86 97 ffcc66
8 86 97 ffcc66
9 86 97 ffcc66
10 86 97 ffcc66
11 86 97 ffcc66
12 86 97 ffcc66
13 86 97 ffcc66
14 86 97 ffcc66
15 86 97 ffcc66
6 87 97 ffcc66
7 87 97 ffcc66
8 87 97 ffcc66
9 87 97 ffcc66
10 87 97 ffcc66
11 87 97 ffcc66
12 87 97 ffcc66
13 87 97 ffcc66
14 87 97 ffcc66
9 88 97 ffcc66
10 88 97 ffcc66
11 88 97 ffcc66
12 88 97 ffcc66
0 80 98 ffcc66
1 80 98 ffcc66
2 80 98 ffcc66
3 80 98 ffcc66
4 80 98 ffcc66
5 80 98 ffcc66
6 80 98 ffcc66
7 80 98 ffcc66
8 80 98 ffcc66
9 80 98 ffcc66
10 80 98 ffcc66
11 80 98 ffcc66
12 80 98 ffcc66
13 80 98 ffcc66
14 80 98 ffcc66
15 80 98 ffcc66
0 81 98 ffcc66
1 81 98 ffcc66
2 81 98 ffcc66
3 81 98 ee0000
4 81 98 ffcc66
5 81 98 ffcc66
6 81 98 ffcc66
7 81 98 ffcc66
8 81 98 ffcc66
9 81 98 ffcc66
10 81 98 ffcc66
11 81 98 ffcc66
12 81 98 ffcc66
13 81 98 ffcc66
14 81 98 ffcc66
15 81 98 ffcc66
0 82 98 ffcc66
1 82 98 ffcc66
2 82 98 ffcc66
3 82 98 ffcc66
4 82 98 ee0000
5 82 98 ee0000
6 82 98 ee0000
7 82 98 bbbbbb
8 82 98 bbbbbb
9 82 98 bbbbbb
10 82 98 bbbbbb
11 82 98 ffcc66
12 82 98 ffcc66
13 82 98 ffcc66
14 82 98 ffcc66
15 82 98 ffcc66
0 83 98 ffcc66
2 83 98 ffcc66
3 83 98 ffcc66
4 83 98 ee0000
5 83 98 ee0000
6 83 98 ee0000
7 83 98 ee0000
8 83 98 bbbbbb
9 83 98 bbbbbb
10 83 98 bbbbbb
11 83 98 ee0000
12 83 98 ee0000
13 83 98 ffcc66
14 83 98 ffcc66
15 83 98 ffcc66
0 84 98 ffcc66
3 84 98 ffcc66
4 84 98 ffcc66
5 84 98 ee0000
6 84 98 ee0000
7 84 98 ee0000
8 84 98 ee0000
9 84 98 ee0000
10 84 98 ee0000
11 84 98 ee0000
12 84 98 ee0000
13 84 98 ee0000
14 84 98 ee0000
15 84 98 ffcc66
3 85 98 ffcc66
4 85 98 ffcc66
5 85 98 ffcc66
6 85 98 ee0000
7 85 98 ee0000
8 85 98 ee0000
9 85 98 ee0000
10 85 98 ee0000
11 85 98 ee0000
12 85 98 ee0000
13 85 98 ee0000
14 85 98 ee0000
15 85 98 ffcc66
4 86 98 ffcc66
5 86 98 ffcc66
6 86 98 ffcc66
7 86 98 ee0000
8 86 98 ee0000
9 86 98 ee0000
10 86 98 ee0000
11 86 98 ee0000
12 86 98 ee0000
13 86 98 ee0000
14 86 98 ffcc66
15 86 98 ffcc66
6 87 98 ffcc66
7 87 98 ffcc66
8 87 98 ffcc66
9 87 98 ffcc66
10 87 98 ee0000
11 87 98 ee0000
12 87 98 ffcc66
13 87 98 ffcc66
14 87 98 ffcc66
9 88 98 ffcc66
10 88 98 ffcc66
11 88 98 ffcc66
12 88 98 ffcc66
13 88 98 ffcc66
0 80 99 ee0000
1 80 99 ffcc66
2 80 99 ffcc66
3 80 99 ee0000
4 80 99 ee0000
5 80 99 ee0000
6 80 99 bbbbbb
7 80 99 bbbbbb
8 80 99 bbbbbb
9 80 99 bbbbbb
10 80 99 bbbbbb
11 80 99 bbbbbb
12 80 99 bbbbbb
13 80 99 ee0000
14 80 99 ee0000
15 80 99 ee0000
0 81 99 ee0000
1 81 99 ffcc66
2 81 99 ffcc66
3 81 99 ee0000
4 81 99 ee0000
5 81 99 ee0000
6 81 99 bbbbbb
7 81 99 bbbbbb
8 81 99 bbbbbb
9 81 99 bbbbbb
10 81 99 bbbbbb
11 81 99 bbbbbb
12 81 99 bbbbbb
13 81 99 ee0000
14 81 99 ee0000
15 81 99 ee0000
0 82 99 ffcc66
1 82 99 ffcc66
2 82 99 ffcc66
3 82 99 ee0000
4 82 99 ee0000
5 82 99 ee0000
6 82 99 ee0000
7 82 99 bbbbbb
8 82 99 bbbbbb
9 82 99 bbbbbb
10 82 99 bbbbbb
11 82 99 bbbbbb
12 82 99 ee0000
13 82 99 ee0000
14 82 99 ee0000
15 82 99 ee0000
0 83 99 ffcc66
1 83 99 ffcc66
2 83 99 ffcc66
3 83 99 ffcc66
4 83 99 ee0000
5 83 99 ee0000
6 83 99 ee0000
7 83 99 ee0000
8 83 99 bbbbbb
9 83 99 bbbbbb
10 83 99 bbbbbb
11 83 99 ee0000
12 83 99 ee0000
13 83 99 ee0000
14 83 99 ee0000
15 83 99 ee0000
0 84 99 ffcc66
2 84 99 ffcc66
3 84 99 ffcc66
4 84 99 ee0000
5 84 99 ee0000
6 84 99 ee0000
7 84 99 ee0000
8 84 99 ee0000
9 84 99 ee0000
10 84 99 ee0000
11 84 99 ee0000
12 84 99 ee0000
13 84 99 ee0000
14 84 99 ee0000
15 84 99 ee0000
0 85 99 ffcc66
3 85 99 ffcc66
4 85 99 ffcc66
5 85 99 ee0000
6 85 99 ee0000
7 85 99 ee0000
8 85 99 ee0000
9 85 99 ee0000
10 85 99 ee0000
11 85 99 ee0000
12 85 99 ee0000
13 85 99 ee0000
14 85 99 ee0000
15 85 99 ffcc66
4 86 99 ffcc66
5 86 99 ffcc66
6 86 99 ffcc66
7 86 99 ee0000
8 86 99 ee0000
9 86 99 ee0000
10 86 99 ee0000
11 86 99 ee0000
12 86 99 ee0000
13 86 99 ee0000
14 86 99 ffcc66
15 86 99 ffcc66
5 87 99 ffcc66
6 87 99 ffcc66
7 87 99 ffcc66
8 87 99 ffcc66
9 87 99 ffcc66
10 87 99 ee0000
11 87 99 ee0000
12 87 99 ee0000
13 87 99 ffcc66
14 87 99 ffcc66
9 88 99 ffcc66
10 88 99 ffcc66
11 88 99 ffcc66
12 88 99 ffcc66
13 88 99 ffcc66
0 80 100 ee0000
1 80 100 ffcc66
2 80 100 ffcc66
3 80 100 ee0000
4 80 100 ee0000
5 80 100 ee0000
6 80 100 bbbbbb
7 80 100 bbbbbb
8 80 100 bbbbbb
9 80 100 bbbbbb
10 80 100 bbbbbb
11 80 100 bbbbbb
12 80 100 bbbbbb
13 80 100 ee0000
14 80 100 ee0000
15 80 100 ee0000
0 81 100 ee0000
1 81 100 ffcc66
2 81 100 ffcc66
3 81 100 ee0000
4 81 100 ee0000
5 81 100 ee0000
6 81 100 bbbbbb
7 81 100 bbbbbb
8 81 100 bbbbbb
9 81 100 bbbbbb
10 81 100 bbbbbb
11 81 100 bbbbbb
12 81 100 bbbbbb
13 81 100 ee0000
14 81 100 ee0000
15 81 100 ee0000
0 82 100 ee0000
1 82 100 ffcc66
2 82 100 ffcc66
3 82 100 ee0000
4 82 100 ee0000
5 82 100 ee0000
6 82 100 ee0000
7 82 100 bbbbbb
8 82 100 bbbbbb
9 82 100 bbbbbb
10 82 100 bbbbbb
11 82 100 bbbbbb
12 82 100 ee0000
13 82 100 ee0000
14 82 100 ee0000
15 82 100 ee0000
0 83 100 ffcc66
1 83 100 ffcc66
2 83 100 ffcc66
3 83 100 ee0000
4 83 100 ee0000
5 83 100 ee0000
6 83 100 ee0000
7 83 100 ee0000
8 83 100 bbbbbb
9 83 100 bbbbbb
10 83 100 bbbbbb
11 83 100 ee0000
12 83 100 ee0000
13 83 100 ee0000
14 83 100 ee0000
15 83 100 ee0000
0 84 100 ffcc66
1 84 100 ffcc66
2 84 100 ffcc66
3 84 100 ffcc66
4 84 100 ee0000
5 84 100 ee0000
6 84 100 ee0000
7 84 100 ee0000
8 84 100 ee0000
9 84 100 ee0000
10 84 100 ee0000
11 84 100 ee0000
12 84 100 ee0000
13 84 100 ee0000
14 84 100 ee0000
15 84 100 ee0000
0 85 100 ffcc66
1 85 100 ffcc66
2 85 100 ffcc66
3 85 100 ffcc66
4 85 100 ffcc66
5 85 100 ee0000
6 85 100 ee0000
7 85 100 ee0000
8 85 100 ee0000
9 85 100 ee0000
10 85 100 ee0000
11 85 100 ee0000
12 85 100 ee0000
13 85 100 ee0000
14 85 100 ee0000
15 85 100 ffcc66
0 86 100 ffcc66
3 86 100 ffcc66
4 86 100 ffcc66
5 86 100 ffcc66
6 86 100 ee0000
7 86 100 ee0000
8 86 100 ee0000
9 86 100 ee0000
10 86 100 ee0000
11 86 100 ee0000
12 86 100 ee0000
13 86 100 ee0000
14 86 100 ffcc66
15 86 100 ffcc66
3 87 100 ffcc66
4 87 100 ffcc66
5 87 100 ffcc66
6 87 100 ffcc66
7 87 100 ffcc66
8 87 100 ffcc66
9 87 100 ffcc66
10 87 100 ee0000
11 87 100 ee0000
12 87 100 ee0000
13 87 100 ffcc66
14 87 100 ffcc66
8 88 100 ffcc66
9 88 100 ffcc66
10 88 100 ffcc66
11 88 100 ffcc66
12 88 100 ffcc66
13 88 100 ffcc66
0 80 101 ee0000
1 80 101 ffcc66
2 80 101 ee0000
3 80 101 ee0000
4 80 101 ee0000
5 80 101 ee0000
6 80 101 bbbbbb
7 80 101 bbbbbb
8 80 101 bbbbbb
9 80 101 bbbbbb
10 80 101 bbbbbb
11 80 101 bbbbbb
12 80 101 bbbbbb
13 80 101 ee0000
14 80 101 ee0000
0 81 101 ee0000
1 81 101 ffcc66
2 81 101 ee0000
3 81 101 ee0000
4 81 101 ee0000
5 81 101 ee0000
6 81 101 bbbbbb
7 81 101 bbbbbb
8 81 101 bbbbbb
9 81 101 bbbbbb
10 81 101 bbbbbb
11 81 101 bbbbbb
12 81 101 bbbbbb
13 81 101 ee0000
14 81 101 ee0000
0 82 101 ee0000
1 82 101 ffcc66
2 82 101 ee0000
3 82 101 ee0000
4 82 101 ee0000
5 82 101 ee0000
6 82 101 ee0000
7 82 101 bbbbbb
8 82 101 bbbbbb
9 82 101 bbbbbb
10 82 101 bbbbbb
11 82 101 bbbbbb
12 82 101 ee0000
13 82 101 ee0000
14 82 101 ee0000
0 83 101 ee0000
1 83 101 ffcc66
2 83 101 ffcc66
3 83 101 ee0000
4 83 101 ee0000
5 83 101 ee0000
6 83 101 ee0000
7 83 101 ee0000
8 83 101 bbbbbb
9 83 101 bbbbbb
10 83 101 bbbbbb
11 83 101 ee0000
12 83 101 ee0000
13 83 101 ee0000
14 83 101 ee0000
0 84 101 ee0000
1 84 101 ffcc66
2 84 101 ffcc66
3 84 101 ee0000
4 84 101 ee0000
5 84 101 ee0000
6 84 101 ee0000
7 84 101 ee0000
8 84 101 ee0000
9 84 101 ee0000
10 84 101 ee0000
11 84 101 ee0000
12 84 101 ee0000
13 84 101 ee0000
14 84 101 ee0000
15 84 101 ffcc66
0 85 101 ffcc66
1 85 101 ffcc66
2 85 101 ffcc66
3 85 101 ffcc66
4 85 101 ee0000
5 85 101 ee0000
6 85 101 ee0000
7 85 101 ee0000
8 85 101 ee0000
9 85 101 ee0000
10 85 101 ee0000
11 85 101 ee0000
12 85 101 ee0000
13 85 101 ee0000
14 85 101 ee0000
15 85 101 ffcc66
0 86 101 ffcc66
1 86 101 ffcc66
2 86 101 ffcc66
3 86 101 ffcc66
4 86 101 ffcc66
5 86 101 ee0000
6 86 101 ee0000
7 86 101 ee0000
8 86 101 ee0000
9 86 101 ee0000
10 86 101 ee0000
11 86 101 ee0000
12 86 101 ee0000
13 86 101 ee0000
14 86 101 ffcc66
15 86 101 ffcc66
0 87 101 ffcc66
1 87 101 ffcc66
2 87 101 ffcc66
3 87 101 ffcc66
4 87 101 ffcc66
5 87 101 ffcc66
6 87 101 ffcc66
7 87 101 ffcc66
8 87 101 ffcc66
9 87 101 ee0000
10 87 101 ee0000
11 87 101 ee0000
12 87 101 ee0000
